Workbook

Sheet Informatie
A1: Bemonsteringsdata: 13 oktober t/m 30 oktober 2025
A3: Op alle locaties is een Van Veenhapper gebruikt met bemonsteringsoppervlak van 260 cm2
A4: Op elke locatie zijn 5 happen genomen, binnen 100 meter vanaf de hoofdlocatie
A6: Asvrij droog vleesgewicht (ADV) bepaald van driehoeks- en quaggamosselen (dit voor beide methoden (vlees verwijderd en schelp aan 1 kant open))
A7: Drooggewicht: 48 uur bij 760 graden C.
A8: Asrest: 4 uur bij 490 graden C.
A10: Sedimenttype: | D10: Percentage lutumgehalte | H10: PAS= Primair aanhechtingsubstraat:
A11: K | B11: Klei | D11: Omschrijving | E11: Beoordeling | F11: Percentage | H11: D | I11: Dreissena
A12: Z | B12: Zand | D12: Klei-arm zand. Strandzand | E12: Schuurt tussen duim en wijsvinger. | F12: 0-2% | H12: M | I12: Mytilus
A13: Z/s | B13: Meest zand (met slib) | D13: Kleihoudend zand | E13: Iets vuil, smeert ietsje. Schuurt nog onverminderd, klein slibwolkje als je het in een plas gooit. | F13: 2-5% | H13: C | I13: Corbicula
A14: V | B14: Veen | D14: Kleiig zand/ slibbig zand | E14: Smeert. Bij knijpen gaat een klein deel tussen de vingers door. | F14: 5-8% | H14: Z | I14: Zuiderzeeschelpen
A15: S | B15: Slib | D15: Zeer lichte zavel | E15: Smeert goed. Bij knijpen grotendeels weg, iets zand over in de hand. | F15: 8-12% | H15: N | I15: Najaden (o.a. zwanenmossels)
A16: S/z | B16: Meest slib (met zand) | D16: Matig lichte zavel | E16: Smeert goed. Zand alleen nog goed te voelen tussen duim en wijsvinger. | F16: 12-17% | H16: W | I16: Waterplanten
A17: G | B17: Grind | D17: Zware zavel | E17: Smeert goed. Bijna geen zand meer te voelen. Klei wil niet meer van vingers afspoelen. | F17: 17-25% | I17: Overig
A18: X | B18: Grof materiaal (stenen, schelpen) | D18: Lichte klei | E18: Bijna stopverf, als molykote tussen duim en vinger. Zand alleen nog te proeven. | F18: 25-35%
A19: Y | B19: Anders | D19: Zware klei | E19: Bijna stopverf, als molykote tussen duim en vinger. Geen zand meer te proeven. | F19: >35%

Sheet Bijlage 4
O1: k: klei, z: zand, z/s: meest zand met slib, v: veen | Y1: D: Dreissena, M: Mytilus, C: Corbicula, Z: zuiderzeeschelpen
O2: s: slib, s/z: meest slib met zand, g: grind, x: grof materiaal | Y2: N: Najaden, W: waterplanten, O: overig
C3: Coordinaten gepland (RD) | E3: Coordinaten uitgevoerd (RD) | I3: Biovolumes (ml) | K3: Biovolume (ml) | M3: Aantallen | O3: Sedimenttype (k, z, z/s, v, y, s, s/z, g, x) per hap | T3: Percentage lutum per hap | Y3: PAS (D, M, C, Z, N, W, O) per hap
A4: Deelgebied | B4: Locatie | C4: x | D4: y | E4: x | F4: y | G4: Datum | H4: Waterdiepte (m) | I4: Driehoeksmossel | J4: Quaggamossel | K4: Mytilidae | L4: Corbicula | M4: Corbicula | N4: Najaden | O4: 1 | P4: 2 | Q4: 3 | R4: 4 | S4: 5 | T4: 1 | U4: 2 | V4: 3 | W4: 4 | X4: 5 | Y4: 1 | Z4: 2 | AA4: 3 | AB4: 4 | AC4: 5 | AD4: Monsters lab | AE4: Weer | AF4: Opmerkingen
A5: IJsselmeer-noord | B5: 1 | C5: 149000 | D5: 563000 | E5: 149011.36 | F5: 563005.36 | G5: 45960.456 | H5: 3.4 | I5: 1.3 | J5: 1.2 | K5: 0 | L5: - | M5: - | N5: - | O5: z | P5: z | Q5: z | R5: z | S5: z | T5: 5-8 | U5: 5-8 | V5: 5-8 | W5: 5-8 | X5: 5-8 | Y5: - | Z5: z | AA5: d | AB5: - | AC5: - | AD5: Nee | AE5: ZW4, 1,2 mm
A6: IJsselmeer-noord | B6: 2 | C6: 153000 | D6: 563000 | E6: 153007.84 | F6: 563004.52 | G6: 45960.475 | H6: 2.74 | I6: - | J6: - | K6: 0 | L6: - | M6: - | N6: - | O6: z | P6: z | Q6: z | R6: z | S6: z | T6: 5-8 | U6: 5-8 | V6: 5-8 | W6: 5-8 | X6: 5-8 | Y6: - | Z6: - | AA6: - | AB6: - | AC6: - | AD6: Nee | AE6: ZW4, 1,2 mm
A7: IJsselmeer-noord | B7: 3 | C7: 147000 | D7: 561000 | E7: 146992.54 | F7: 561002.94 | G7: 45960.44 | H7: 3.2 | I7: - | J7: - | K7: 0 | L7: - | M7: - | N7: - | O7: z | P7: z | Q7: z | R7: z | S7: z | T7: 5-8 | U7: 5-8 | V7: 5-8 | W7: 5-8 | X7: 5-8 | Y7: - | Z7: - | AA7: - | AB7: - | AC7: - | AD7: Nee | AE7: ZW4, 1,2 mm
A8: IJsselmeer-noord | B8: 4 | C8: 151000 | D8: 561000 | E8: 151001.89 | F8: 561008.66 | G8: 45960.491 | H8: 3.16 | I8: - | J8: - | K8: 0 | L8: - | M8: - | N8: - | O8: z | P8: z | Q8: z | R8: z | S8: z | T8: 5-8 | U8: 5-8 | V8: 5-8 | W8: 5-8 | X8: 5-8 | Y8: - | Z8: - | AA8: - | AB8: - | AC8: - | AD8: Nee | AE8: ZW4, 1,2 mm
A9: IJsselmeer-noord | B9: 5 | C9: 145000 | D9: 559000 | E9: 145009.58 | F9: 559011.64 | G9: 45960.423 | H9: 4.82 | I9: 7 | J9: 30 | K9: 0 | L9: - | M9: - | N9: - | O9: z | P9: z/s | Q9: z/s | R9: z/s | S9: z/s | T9: 8-12 | U9: 12-17 | V9: 12-17 | W9: 12-17 | X9: 12-17 | Y9: d | Z9: d | AA9: d | AB9: d | AC9: d | AD9: Nee | AE9: ZW4, 1,2 mm
A10: IJsselmeer-noord | B10: 6 | C10: 149000 | D10: 559000 | E10: 148987.97 | F10: 559015.43 | G10: 45960.507 | H10: 4.78 | I10: - | J10: - | K10: 0 | L10: - | M10: - | N10: - | O10: z/s | P10: z/s | Q10: s | R10: z/s | S10: z | T10: 8-12 | U10: 12-17 | V10: 17-25 | W10: 12-17 | X10: 5-8 | Y10: - | Z10: - | AA10: - | AB10: - | AC10: - | AD10: Nee | AE10: ZW4, 1,2 mm
A11: IJsselmeer-noord | B11: 7 | C11: 153000 | D11: 559000 | E11: 152986 | F11: 558995.76 | G11: 45959.404 | H11: 6.68 | I11: 0.3 | J11: 2 | K11: 0 | L11: - | M11: - | N11: - | O11: s | P11: z | Q11: s | R11: s | S11: z | T11: 17-25 | U11: 5-8 | V11: 17-25 | W11: 17-25 | X11: 5-8 | Y11: - | Z11: d | AA11: - | AB11: - | AC11: - | AD11: Nee | AE11: ZW4-5, 8,6 mm
A12: IJsselmeer-noord | B12: 8 | C12: 143000 | D12: 557000 | E12: 143009.28 | F12: 557019.09 | G12: 45960.407 | H12: 4.94 | I12: - | J12: - | K12: 0 | L12: - | M12: - | N12: - | O12: z | P12: z/s | Q12: z | R12: z | S12: z/s | T12: 5-8 | U12: 12-17 | V12: 5-8 | W12: 5-8 | X12: 12-17 | Y12: - | Z12: - | AA12: - | AB12: - | AC12: - | AD12: Nee | AE12: ZW4, 1,2 mm
A13: IJsselmeer-noord | B13: 9 | C13: 147000 | D13: 557000 | E13: 146997.06 | F13: 556997.74 | G13: 45960.523 | H13: 4.88 | I13: 2 | J13: 0.4 | K13: 0 | L13: - | M13: - | N13: - | O13: z/s | P13: z/s | Q13: z/s | R13: z/s | S13: z/s | T13: 8-12 | U13: 8-12 | V13: 8-12 | W13: 8-12 | X13: 8-12 | Y13: - | Z13: - | AA13: d | AB13: - | AC13: - | AD13: Nee | AE13: ZW4, 1,2 mm
A14: IJsselmeer-noord | B14: 10 | C14: 151000 | D14: 557000 | E14: 151001.87 | F14: 556993.68 | G14: 45959.422 | H14: 5.275 | I14: - | J14: - | K14: 0 | L14: - | M14: - | N14: - | O14: s | P14: s | Q14: z | R14: z | S14: s | T14: 17-25 | U14: 17-25 | V14: 5-8 | W14: 5-8 | X14: 17-25 | Y14: - | Z14: - | AA14: - | AB14: - | AC14: - | AD14: Nee | AE14: ZW4-5, 8,6 mm | AF14: Laatste coordinaat en waterdiepte niet genoteerd
A15: IJsselmeer-noord | B15: 11 | C15: 154700 | D15: 556900 | E15: 154693.21 | F15: 556900.91 | G15: 45959.389 | H15: 2.6 | I15: 0.05 | J15: - | K15: 0 | L15: - | M15: - | N15: - | O15: z | P15: z | Q15: z | R15: z | S15: z | T15: 5-8 | U15: 5-8 | V15: 5-8 | W15: 5-8 | X15: 5-8 | Y15: - | Z15: - | AA15: - | AB15: - | AC15: - | AD15: Nee | AE15: ZW4-5, 8,6 mm
A16: IJsselmeer-noord | B16: 12 | C16: 141000 | D16: 555000 | E16: 140997.29 | F16: 555012.94 | G16: 45960.39 | H16: 5.76 | I16: 0.2 | J16: 0.1 | K16: 0 | L16: - | M16: - | N16: - | O16: z/s | P16: z/s | Q16: z/s | R16: z | S16: s | T16: 12-17 | U16: 12-17 | V16: 12-17 | W16: 8-12 | X16: 17-25 | Y16: - | Z16: - | AA16: d | AB16: - | AC16: z | AD16: Nee | AE16: ZW4, 1,2 mm
A17: IJsselmeer-noord | B17: 13 | C17: 145000 | D17: 555000 | E17: 145000.64 | F17: 554997.25 | G17: 45960.538 | H17: 3.88 | I17: - | J17: - | K17: 0 | L17: - | M17: - | N17: - | O17: z | P17: z | Q17: z | R17: z | S17: z | T17: 5-8 | U17: 5-8 | V17: 5-8 | W17: 5-8 | X17: 5-8 | Y17: - | Z17: - | AA17: - | AB17: - | AC17: - | AD17: Nee | AE17: ZW4, 1,2 mm
A18: IJsselmeer-noord | B18: 14 | C18: 149000 | D18: 555000 | E18: 148996.86 | F18: 555022.27 | G18: 45960.571 | H18: 4.6 | I18: - | J18: - | K18: 0 | L18: - | M18: - | N18: - | O18: z | P18: z | Q18: z | R18: z | S18: z | T18: 5-8 | U18: 5-8 | V18: 5-8 | W18: 5-8 | X18: 5-8 | Y18: - | Z18: - | AA18: - | AB18: - | AC18: - | AD18: Nee | AE18: ZW4, 1,2 mm
A19: IJsselmeer-noord | B19: 15 | C19: 153000 | D19: 555000 | E19: 152988.31 | F19: 554995.16 | G19: 45959.372 | H19: 3.46 | I19: - | J19: - | K19: 0 | L19: - | M19: - | N19: - | O19: z | P19: z | Q19: z | R19: z | S19: z | T19: 2-5 | U19: 2-5 | V19: 2-5 | W19: 2-5 | X19: 2-5 | Y19: - | Z19: - | AA19: - | AB19: - | AC19: - | AD19: Nee | AE19: ZW4-5, 8,6 mm
A20: IJsselmeer-noord | B20: 16 | C20: 139000 | D20: 553000 | E20: 138996.38 | F20: 553001.92 | G20: 45951.522 | H20: 4.02 | I20: 2.3 | J20: 1 | K20: 0 | L20: - | M20: - | N20: - | O20: z | P20: z | Q20: z | R20: z | S20: z | T20: 5-8 | U20: 5-8 | V20: 5-8 | W20: 5-8 | X20: 5-8 | Y20: - | Z20: d | AA20: d | AB20: - | AC20: d | AD20: Nee | AE20: ZW4, 8,1 mm
A21: IJsselmeer-noord | B21: 17 | C21: 143000 | D21: 553000 | E21: 142998.53 | F21: 552997.72 | G21: 45960.375 | H21: 4.64 | I21: 9 | J21: 30 | K21: 0 | L21: - | M21: - | N21: - | O21: z | P21: z | Q21: z | R21: z | S21: z | T21: 5-8 | U21: 5-8 | V21: 5-8 | W21: 5-8 | X21: 5-8 | Y21: d | Z21: d | AA21: d | AB21: d | AC21: d | AD21: Nee | AE21: ZW4, 1,2 mm
A22: IJsselmeer-noord | B22: 18 | C22: 147000 | D22: 553000 | E22: 147012.31 | F22: 553003.36 | G22: 45960.553 | H22: 4.78 | I22: 3.5 | J22: 1.6 | K22: 0 | L22: - | M22: - | N22: - | O22: z | P22: z | Q22: z | R22: z | S22: z | T22: 8-12 | U22: 8-12 | V22: 8-12 | W22: 8-12 | X22: 5-8 | Y22: z | Z22: - | AA22: z | AB22: - | AC22: z | AD22: Nee | AE22: ZW4, 1,2 mm
A23: IJsselmeer-noord | B23: 19 | C23: 151000 | D23: 553000 | E23: 151042.16 | F23: 552966.36 | G23: 45959.451 | H23: 5.34 | I23: 0.2 | J23: 3 | K23: 0 | L23: - | M23: - | N23: - | O23: z | P23: z | Q23: z | R23: z | S23: z | T23: 5-8 | U23: 5-8 | V23: 5-8 | W23: 5-8 | X23: 5-8 | Y23: x | Z23: - | AA23: - | AB23: - | AC23: - | AD23: Nee | AE23: ZW4-5, 8,6 mm | AF23: x is steen
A24: IJsselmeer-noord | B24: 20 | C24: 155000 | D24: 553000 | E24: 155006.42 | F24: 553014.05 | G24: 45959.357 | H24: 3.56 | I24: - | J24: - | K24: 0 | L24: - | M24: - | N24: - | O24: z | P24: z | Q24: z | R24: z | S24: z | T24: 2-5 | U24: 2-5 | V24: 2-5 | W24: 2-5 | X24: 2-5 | Y24: - | Z24: - | AA24: - | AB24: - | AC24: - | AD24: Nee | AE24: ZW4-5, 8,6 mm
A25: IJsselmeer-noord | B25: 21 | C25: 137000 | D25: 551000 | E25: 136996.4 | F25: 551001.52 | G25: 45951.539 | H25: 5.32 | I25: 1.6 | J25: 9.5 | K25: 0 | L25: - | M25: - | N25: - | O25: z | P25: z | Q25: z | R25: z | S25: s | T25: 5-8 | U25: 5-8 | V25: 5-8 | W25: 8-12 | X25: 17-25 | Y25: d | Z25: d | AA25: d | AB25: d | AC25: - | AD25: Ja | AE25: ZW4, 8,1 mm
A26: IJsselmeer-noord | B26: 22 | C26: 141000 | D26: 551000 | E26: 141006.82 | F26: 551027.25 | G26: 45951.506 | H26: 4.84 | I26: 3.5 | J26: 99 | K26: 0 | L26: - | M26: - | N26: - | O26: z,x | P26: z | Q26: z | R26: z | S26: z | T26: 5-8 | U26: 5-8 | V26: 5-8 | W26: 5-8 | X26: 5-8 | Y26: d | Z26: d | AA26: d | AB26: d | AC26: d | AD26: Ja | AE26: ZW4, 8,1 mm
A27: IJsselmeer-noord | B27: 23 | C27: 145000 | D27: 551000 | E27: 144987.92 | F27: 551010.62 | G27: 45960.36 | H27: 4.18 | I27: 2 | J27: 0.3 | K27: 0 | L27: - | M27: - | N27: - | O27: z | P27: z | Q27: z | R27: z | S27: z | T27: 5-8 | U27: 5-8 | V27: 5-8 | W27: 5-8 | X27: 5-8 | Y27: - | Z27: - | AA27: d | AB27: z | AC27: - | AD27: Nee | AE27: ZW4, 1,2 mm
A28: IJsselmeer-noord | B28: 24 | C28: 149000 | D28: 551000 | E28: 148990.21 | F28: 551009.14 | G28: 45960.587 | H28: 5.46 | I28: 0.1 | J28: 0.05 | K28: 0 | L28: - | M28: - | N28: - | O28: z | P28: z | Q28: z | R28: z | S28: z | T28: 8-12 | U28: 8-12 | V28: 8-12 | W28: 8-12 | X28: 8-12 | Y28: - | Z28: - | AA28: - | AB28: - | AC28: d | AD28: Nee | AE28: ZW4, 1,2 mm
A29: IJsselmeer-noord | B29: 25 | C29: 153000 | D29: 551000 | E29: 153004.26 | F29: 550991.04 | G29: 45952.582 | H29: 4.22 | I29: 0.3 | J29: - | K29: 0 | L29: - | M29: - | N29: - | O29: z | P29: z | Q29: z | R29: z | S29: z | T29: 5-8 | U29: 5-8 | V29: 5-8 | W29: 5-8 | X29: 5-8 | Y29: - | Z29: - | AA29: - | AB29: z | AC29: - | AD29: Nee | AE29: ZW3, 0,4 mm
A30: IJsselmeer-noord | B30: 26 | C30: 135000 | D30: 549000 | E30: 134995.01 | F30: 549010.18 | G30: 45951.56 | H30: 2.96 | I30: 2.6 | J30: 4 | K30: 0 | L30: 5 | M30: 18 | N30: - | O30: z | P30: z | Q30: z | R30: z | S30: z | T30: 5-8 | U30: 5-8 | V30: 5-8 | W30: 5-8 | X30: 5-8 | Y30: z,c | Z30: d | AA30: d | AB30: d | AC30: d | AD30: Nee | AE30: ZW4, 8,1 mm
A31: IJsselmeer-noord | B31: 27 | C31: 139000 | D31: 549000 | E31: 138984.44 | F31: 548995.39 | G31: 45951.487 | H31: 2.34 | I31: 1 | J31: 1.1 | K31: 0 | L31: 7.5 | M31: 15 | N31: - | O31: z | P31: z | Q31: z | R31: z | S31: z | T31: 5-8 | U31: 5-8 | V31: 5-8 | W31: 5-8 | X31: 5-8 | Y31: - | Z31: - | AA31: - | AB31: d | AC31: - | AD31: Nee | AE31: ZW4, 8,1 mm
A32: IJsselmeer-noord | B32: 28 | C32: 143000 | D32: 549000 | E32: 142996.72 | F32: 549003.51 | G32: 45951.415 | H32: 5.48 | I32: - | J32: - | K32: 0 | L32: - | M32: - | N32: - | O32: z | P32: z | Q32: z | R32: z | S32: z | T32: 8-12 | U32: 8-12 | V32: 8-12 | W32: 8-12 | X32: 8-12 | Y32: - | Z32: - | AA32: - | AB32: - | AC32: - | AD32: Nee | AE32: ZW4, 8,1 mm
A33: IJsselmeer-noord | B33: 29 | C33: 147000 | D33: 549000 | E33: 147000 | F33: 549000 | G33: 45960 | H33: 4.58 | I33: 1.4 | J33: 0.8 | K33: 0 | L33: - | M33: - | N33: - | O33: z | P33: z | Q33: z | R33: z | S33: z | T33: 5-8 | U33: 5-8 | V33: 5-8 | W33: 5-8 | X33: 5-8 | Y33: - | Z33: - | AA33: z | AB33: - | AC33: d | AD33: Nee | AE33: ZW4, 1,2 mm | AF33: GPS had even kuren, geen coordinaat
A34: IJsselmeer-noord | B34: 30 | C34: 151000 | D34: 549000 | E34: 150998.79 | F34: 549006.03 | G34: 45952.566 | H34: 4.66 | I34: - | J34: - | K34: 0 | L34: - | M34: - | N34: - | O34: z | P34: z | Q34: z | R34: z | S34: z | T34: 5-8 | U34: 5-8 | V34: 5-8 | W34: 5-8 | X34: 5-8 | Y34: - | Z34: - | AA34: - | AB34: - | AC34: - | AD34: Nee | AE34: ZW3, 0,4 mm
A35: IJsselmeer-noord | B35: 31 | C35: 155000 | D35: 549000 | E35: 154977.85 | F35: 548991.7 | G35: 45952.599 | H35: 2.86 | I35: - | J35: - | K35: 0 | L35: - | M35: - | N35: - | O35: z | P35: z | Q35: z | R35: z | S35: z | T35: 2-5 | U35: 2-5 | V35: 2-5 | W35: 2-5 | X35: 2-5 | Y35: - | Z35: - | AA35: - | AB35: - | AC35: - | AD35: Nee | AE35: ZW3, 0,4 mm
A36: IJsselmeer-noord | B36: 32 | C36: 133200 | D36: 547000 | E36: 133193.34 | F36: 546990.51 | G36: 45951.577 | H36: 3.6 | I36: - | J36: - | K36: 0 | L36: - | M36: - | N36: - | O36: k,v | P36: k | Q36: z/s | R36: z/s | S36: k | T36: 17-25 | U36: 25-35 | V36: 12-17 | W36: 12-17 | X36: 25-35 | Y36: - | Z36: - | AA36: - | AB36: - | AC36: - | AD36: Nee | AE36: ZW4, 8,1 mm
A37: IJsselmeer-noord | B37: 33 | C37: 137000 | D37: 547000 | E37: 136992.17 | F37: 546996.31 | G37: 45951.466 | H37: 3.26 | I37: 2 | J37: 2 | K37: 0 | L37: - | M37: - | N37: - | O37: z | P37: z | Q37: z | R37: z | S37: z | T37: 5-8 | U37: 5-8 | V37: 5-8 | W37: 5-8 | X37: 5-8 | Y37: d,z | Z37: d | AA37: - | AB37: d,z | AC37: d | AD37: Nee | AE37: ZW4, 8,1 mm
A38: IJsselmeer-noord | B38: 34 | C38: 141000 | D38: 547000 | E38: 140990.89 | F38: 546995.49 | G38: 45951.432 | H38: 5.2 | I38: 1.2 | J38: 116 | K38: 0 | L38: - | M38: - | N38: - | O38: z | P38: z | Q38: z | R38: z | S38: z | T38: 8-12 | U38: 8-12 | V38: 8-12 | W38: 8-12 | X38: 8-12 | Y38: d | Z38: d | AA38: d | AB38: d | AC38: d | AD38: Ja | AE38: ZW4, 8,1 mm
A39: IJsselmeer-noord | B39: 35 | C39: 145000 | D39: 547000 | E39: 145007.37 | F39: 547002.15 | G39: 45951.399 | H39: 5.2 | I39: 8.5 | J39: 272 | K39: 0 | L39: - | M39: - | N39: - | O39: z,x | P39: z,x | Q39: z,x | R39: z,x | S39: z,x | T39: 5-8 | U39: 5-8 | V39: 5-8 | W39: 5-8 | X39: 5-8 | Y39: d | Z39: d | AA39: d | AB39: d | AC39: d | AD39: Ja | AE39: ZW4, 8,1 mm
A40: IJsselmeer-noord | B40: 36 | C40: 149000 | D40: 547000 | E40: 149003.69 | F40: 546996.92 | G40: 45952.55 | H40: 4.8 | I40: 0.3 | J40: - | K40: 0 | L40: - | M40: - | N40: - | O40: z | P40: z | Q40: z | R40: z | S40: z | T40: 5-8 | U40: 5-8 | V40: 5-8 | W40: 5-8 | X40: 5-8 | Y40: d | Z40: - | AA40: z | AB40: - | AC40: z | AD40: Nee | AE40: ZW3, 0,4 mm
...

Sheet Bijlage 5a
A1: Aantallen aangetroffen mosselen in de meegenomen monsters
A3: Lengteklasse (mm) | B3: IJsselmeer Noord | D3: IJsselmeer Centraal | F3: Ijsselmeer Zuid | H3: Totaal
B4: Bugensis | C4: Polymorpha | D4: Bugensis | E4: Polymorpha | F4: Bugensis | G4: Polymorpha
A5: 2 | B5: 8 | C5: 1 | D5: 3 | E5: 4 | F5: 19 | G5: 1 | H5: =SUM(B5:G5) -> 36
A6: 3 | B6: 40 | C6: 5 | D6: 7 | E6: 1 | F6: 19 | G6: 1 | H6: =SUM(B6:G6) -> 73
A7: 4 | B7: 131 | C7: 17 | D7: 26 | E7: 9 | F7: 22 | G7: 6 | H7: =SUM(B7:G7) -> 211
A8: 5 | B8: 275 | C8: 33 | D8: 125 | E8: 67 | F8: 20 | G8: 10 | H8: =SUM(B8:G8) -> 530
A9: 6 | B9: 405 | C9: 35 | D9: 226 | E9: 118 | F9: 44 | G9: 13 | H9: =SUM(B9:G9) -> 841
A10: 7 | B10: 329 | C10: 38 | D10: 393 | E10: 186 | F10: 66 | G10: 21 | H10: =SUM(B10:G10) -> 1033
A11: 8 | B11: 279 | C11: 23 | D11: 447 | E11: 134 | F11: 48 | G11: 35 | H11: =SUM(B11:G11) -> 966
A12: 9 | B12: 179 | C12: 15 | D12: 432 | E12: 99 | F12: 28 | G12: 31 | H12: =SUM(B12:G12) -> 784
A13: 10 | B13: 126 | C13: 18 | D13: 370 | E13: 64 | F13: 27 | G13: 57 | H13: =SUM(B13:G13) -> 662
A14: 11 | B14: 67 | C14: 24 | D14: 156 | E14: 29 | F14: 11 | G14: 62 | H14: =SUM(B14:G14) -> 349
A15: 12 | B15: 74 | C15: 18 | D15: 98 | E15: 11 | F15: 17 | G15: 56 | H15: =SUM(B15:G15) -> 274
A16: 13 | B16: 85 | C16: 18 | D16: 69 | E16: 19 | F16: 28 | G16: 36 | H16: =SUM(B16:G16) -> 255
... A21: 18 | B21: 171 | C21: 2 | D21: 96 | E21: 4 | F21: 170 | G21: 1 | H21: =SUM(B21:G21) -> 444
A22: 19 | B22: 153 | D22: 59 | E22: 2 | F22: 146 | G22: 1 | H22: =SUM(B22:G22) -> 361
A23: 20 | B23: 130 | D23: 88 | E23: 2 | F23: 129 | G23: 0 | H23: =SUM(B23:G23) -> 349
A24: 21 | B24: 81 | D24: 78 | E24: 0 | F24: 78 | G24: 2 | H24: =SUM(B24:G24) -> 239
A25: 22 | B25: 57 | D25: 88 | E25: 1 | F25: 53 | H25: =SUM(B25:G25) -> 199
A26: 23 | B26: 33 | D26: 62 | F26: 20 | H26: =SUM(B26:G26) -> 115
A27: 24 | B27: 11 | D27: 23 | F27: 5 | H27: =SUM(B27:G27) -> 39
A28: 25 | B28: 6 | D28: 17 | H28: =SUM(B28:G28) -> 23
A29: 26 | B29: 1 | D29: 13 | H29: =SUM(B29:G29) -> 14
A30: 27 | B30: 1 | D30: 6 | H30: =SUM(B30:G30) -> 7
A31: 28 | B31: 1 | D31: 2 | H31: =SUM(B31:G31) -> 3
A32: 29 | H32: =SUM(B32:G32) -> 0
A33: 30 | H33: =SUM(B33:G33) -> 0
A34: 31 | H34: =SUM(B34:G34) -> 0
A35: 32 | H35: =SUM(B35:G35) -> 0
A36: 33 | H36: =SUM(B36:G36) -> 0
A37: 34 | H37: =SUM(B37:G37) -> 0
A38: 35 | H38: =SUM(B38:G38) -> 0
A39: 36 | H39: =SUM(B39:G39) -> 0
A40: Totaal | B40: =SUM(B5:B39) -> 3351 | C40: =SUM(C5:C39) -> 271 | D40: =SUM(D5:D39) -> 3245 | E40: =SUM(E5:E39) -> 806 | F40: =SUM(F5:F39) -> 1437 | G40: =SUM(G5:G39) -> 394 | H40: =SUM(H5:H39) -> 9504
D42: biovolume

Sheet Bijlage 5b
A1: Procentuele verspreiding van de lengteklassen per soort per deelgebied
A3: Lengteklasse (mm) | B3: IJsselmeer Noord | D3: IJsselmeer Centraal | F3: IJsselmeer Zuid
B4: Bugensis | C4: Polymorpha | D4: Bugensis | E4: Polymorpha | F4: Bugensis | G4: Polymorpha
A5: 2 | B5: =('Bijlage 5a'!B5/(SUM('Bijlage 5a'!B$5:B$31))) -> 0.0023873471 | C5: =('Bijlage 5a'!C5/(SUM('Bijlage 5a'!C$5:C$31))) -> 0.0036900369 | D5: =('Bijlage 5a'!D5/(SUM('Bijlage 5a'!D$5:D$31))) -> 0.00092449923 | E5: =('Bijlage 5a'!E5/(SUM('Bijlage 5a'!E$5:E$31))) -> 0.0049627792 | F5: =('Bijlage 5a'!F5/(SUM('Bijlage 5a'!F$5:F$31))) -> 0.01322199 | G5: =('Bijlage 5a'!G5/(SUM('Bijlage 5a'!G$5:G$31))) -> 0.0025380711
A6: 3 | B6: =('Bijlage 5a'!B6/(SUM('Bijlage 5a'!B$5:B$31))) -> 0.011936735 | C6: =('Bijlage 5a'!C6/(SUM('Bijlage 5a'!C$5:C$31))) -> 0.018450185 | D6: =('Bijlage 5a'!D6/(SUM('Bijlage 5a'!D$5:D$31))) -> 0.0021571649 | E6: =('Bijlage 5a'!E6/(SUM('Bijlage 5a'!E$5:E$31))) -> 0.0012406948 | F6: =('Bijlage 5a'!F6/(SUM('Bijlage 5a'!F$5:F$31))) -> 0.01322199 | G6: =('Bijlage 5a'!G6/(SUM('Bijlage 5a'!G$5:G$31))) -> 0.0025380711
A7: 4 | B7: =('Bijlage 5a'!B7/(SUM('Bijlage 5a'!B$5:B$31))) -> 0.039092808 | C7: =('Bijlage 5a'!C7/(SUM('Bijlage 5a'!C$5:C$31))) -> 0.062730627 | D7: =('Bijlage 5a'!D7/(SUM('Bijlage 5a'!D$5:D$31))) -> 0.0080123267 | E7: =('Bijlage 5a'!E7/(SUM('Bijlage 5a'!E$5:E$31))) -> 0.011166253 | F7: =('Bijlage 5a'!F7/(SUM('Bijlage 5a'!F$5:F$31))) -> 0.015309673 | G7: =('Bijlage 5a'!G7/(SUM('Bijlage 5a'!G$5:G$31))) -> 0.015228426
A8: 5 | B8: =('Bijlage 5a'!B8/(SUM('Bijlage 5a'!B$5:B$31))) -> 0.082065055 | C8: =('Bijlage 5a'!C8/(SUM('Bijlage 5a'!C$5:C$31))) -> 0.12177122 | D8: =('Bijlage 5a'!D8/(SUM('Bijlage 5a'!D$5:D$31))) -> 0.038520801 | E8: =('Bijlage 5a'!E8/(SUM('Bijlage 5a'!E$5:E$31))) -> 0.083126551 | F8: =('Bijlage 5a'!F8/(SUM('Bijlage 5a'!F$5:F$31))) -> 0.013917884 | G8: =('Bijlage 5a'!G8/(SUM('Bijlage 5a'!G$5:G$31))) -> 0.025380711
A9: 6 | B9: =('Bijlage 5a'!B9/(SUM('Bijlage 5a'!B$5:B$31))) -> 0.12085944 | C9: =('Bijlage 5a'!C9/(SUM('Bijlage 5a'!C$5:C$31))) -> 0.12915129 | D9: =('Bijlage 5a'!D9/(SUM('Bijlage 5a'!D$5:D$31))) -> 0.069645609 | E9: =('Bijlage 5a'!E9/(SUM('Bijlage 5a'!E$5:E$31))) -> 0.14640199 | F9: =('Bijlage 5a'!F9/(SUM('Bijlage 5a'!F$5:F$31))) -> 0.030619346 | G9: =('Bijlage 5a'!G9/(SUM('Bijlage 5a'!G$5:G$31))) -> 0.032994924
A10: 7 | B10: =('Bijlage 5a'!B10/(SUM('Bijlage 5a'!B$5:B$31))) -> 0.098179648 | C10: =('Bijlage 5a'!C10/(SUM('Bijlage 5a'!C$5:C$31))) -> 0.1402214 | D10: =('Bijlage 5a'!D10/(SUM('Bijlage 5a'!D$5:D$31))) -> 0.1211094 | E10: =('Bijlage 5a'!E10/(SUM('Bijlage 5a'!E$5:E$31))) -> 0.23076923 | F10: =('Bijlage 5a'!F10/(SUM('Bijlage 5a'!F$5:F$31))) -> 0.045929019 | G10: =('Bijlage 5a'!G10/(SUM('Bijlage 5a'!G$5:G$31))) -> 0.053299492
A11: 8 | B11: =('Bijlage 5a'!B11/(SUM('Bijlage 5a'!B$5:B$31))) -> 0.083258729 | C11: =('Bijlage 5a'!C11/(SUM('Bijlage 5a'!C$5:C$31))) -> 0.084870849 | D11: =('Bijlage 5a'!D11/(SUM('Bijlage 5a'!D$5:D$31))) -> 0.13775039 | E11: =('Bijlage 5a'!E11/(SUM('Bijlage 5a'!E$5:E$31))) -> 0.1662531 | F11: =('Bijlage 5a'!F11/(SUM('Bijlage 5a'!F$5:F$31))) -> 0.033402923 | G11: =('Bijlage 5a'!G11/(SUM('Bijlage 5a'!G$5:G$31))) -> 0.088832487
A12: 9 | B12: =('Bijlage 5a'!B12/(SUM('Bijlage 5a'!B$5:B$31))) -> 0.05341689 | C12: =('Bijlage 5a'!C12/(SUM('Bijlage 5a'!C$5:C$31))) -> 0.055350554 | D12: =('Bijlage 5a'!D12/(SUM('Bijlage 5a'!D$5:D$31))) -> 0.13312789 | E12: =('Bijlage 5a'!E12/(SUM('Bijlage 5a'!E$5:E$31))) -> 0.12282878 | F12: =('Bijlage 5a'!F12/(SUM('Bijlage 5a'!F$5:F$31))) -> 0.019485038 | G12: =('Bijlage 5a'!G12/(SUM('Bijlage 5a'!G$5:G$31))) -> 0.078680203
A13: 10 | B13: =('Bijlage 5a'!B13/(SUM('Bijlage 5a'!B$5:B$31))) -> 0.037600716 | C13: =('Bijlage 5a'!C13/(SUM('Bijlage 5a'!C$5:C$31))) -> 0.066420664 | D13: =('Bijlage 5a'!D13/(SUM('Bijlage 5a'!D$5:D$31))) -> 0.11402157 | E13: =('Bijlage 5a'!E13/(SUM('Bijlage 5a'!E$5:E$31))) -> 0.079404467 | F13: =('Bijlage 5a'!F13/(SUM('Bijlage 5a'!F$5:F$31))) -> 0.018789144 | G13: =('Bijlage 5a'!G13/(SUM('Bijlage 5a'!G$5:G$31))) -> 0.14467005
A14: 11 | B14: =('Bijlage 5a'!B14/(SUM('Bijlage 5a'!B$5:B$31))) -> 0.019994032 | C14: =('Bijlage 5a'!C14/(SUM('Bijlage 5a'!C$5:C$31))) -> 0.088560886 | D14: =('Bijlage 5a'!D14/(SUM('Bijlage 5a'!D$5:D$31))) -> 0.04807396 | E14: =('Bijlage 5a'!E14/(SUM('Bijlage 5a'!E$5:E$31))) -> 0.035980149 | F14: =('Bijlage 5a'!F14/(SUM('Bijlage 5a'!F$5:F$31))) -> 0.0076548365 | G14: =('Bijlage 5a'!G14/(SUM('Bijlage 5a'!G$5:G$31))) -> 0.15736041
A15: 12 | B15: =('Bijlage 5a'!B15/(SUM('Bijlage 5a'!B$5:B$31))) -> 0.02208296 | C15: =('Bijlage 5a'!C15/(SUM('Bijlage 5a'!C$5:C$31))) -> 0.066420664 | D15: =('Bijlage 5a'!D15/(SUM('Bijlage 5a'!D$5:D$31))) -> 0.030200308 | E15: =('Bijlage 5a'!E15/(SUM('Bijlage 5a'!E$5:E$31))) -> 0.013647643 | F15: =('Bijlage 5a'!F15/(SUM('Bijlage 5a'!F$5:F$31))) -> 0.011830202 | G15: =('Bijlage 5a'!G15/(SUM('Bijlage 5a'!G$5:G$31))) -> 0.14213198
A16: 13 | B16: =('Bijlage 5a'!B16/(SUM('Bijlage 5a'!B$5:B$31))) -> 0.025365563 | C16: =('Bijlage 5a'!C16/(SUM('Bijlage 5a'!C$5:C$31))) -> 0.066420664 | D16: =('Bijlage 5a'!D16/(SUM('Bijlage 5a'!D$5:D$31))) -> 0.021263482 | E16: =('Bijlage 5a'!E16/(SUM('Bijlage 5a'!E$5:E$31))) -> 0.023573201 | F16: =('Bijlage 5a'!F16/(SUM('Bijlage 5a'!F$5:F$31))) -> 0.019485038 | G16: =('Bijlage 5a'!G16/(SUM('Bijlage 5a'!G$5:G$31))) -> 0.091370558
... A31: 28 | B31: =('Bijlage 5a'!B31/(SUM('Bijlage 5a'!B$5:B$31))) -> 0.00029841838 | C31: =('Bijlage 5a'!C31/(SUM('Bijlage 5a'!C$5:C$31))) -> 0 | D31: =('Bijlage 5a'!D31/(SUM('Bijlage 5a'!D$5:D$31))) -> 0.00061633282 | E31: =('Bijlage 5a'!E31/(SUM('Bijlage 5a'!E$5:E$31))) -> 0 | F31: =('Bijlage 5a'!F31/(SUM('Bijlage 5a'!F$5:F$31))) -> 0 | G31: =('Bijlage 5a'!G31/(SUM('Bijlage 5a'!G$5:G$31))) -> 0
A32: 29
A33: 30
A34: 31
A35: 32
A36: 33
A37: 34
A38: 35
A39: 36
A40: Totaal | B40: =SUM(B5:B39) -> 1 | C40: =SUM(C5:C39) -> 1 | D40: =SUM(D5:D39) -> 1 | E40: =SUM(E5:E39) -> 1 | F40: =SUM(F5:F39) -> 1 | G40: =SUM(G5:G39) -> 1

Sheet Bijlage 6
A1: Gemiddeld ADV van lengteklassen van de quagga- en driehoeksmossel in de deelgebieden
B2: Tabel 2: V4 van A2.120: Schelp aan 1 kant opengemaakt gehaald alvorens te verassen, vlees verast in schelp
A3: SL (mm) | B3: IJsselmeer Noord | F3: IJsselmeer Centraal | J3: IJsselmeer Zuid
B4: D. bugensis | D4: D. polymorpha | F4: D. bugensis | H4: D. polymorpha | J4: D. bugensis | L4: D. polymorpha
B5: ADV/mossel | C5: N bugensis | D5: ADV/mossel | E5: N polymorpha | F5: ADV/mossel | G5: N bugensis | H5: ADV/mossel | I5: N polymorpha | J5: ADV/mossel | K5: N bugensis | L5: ADV/mossel | M5: N polymorpha
A6: 7 | B6: 1.09 | C6: 40 | D6: 1.43 | E6: 38 | F6: 1.21 | G6: 40 | H6: 1.6975 | I6: 40 | J6: 1.25 | K6: 40 | L6: 1.76 | M6: 21
A7: 8 | B7: 1.62 | C7: 40 | D7: 2.76 | E7: 23 | F7: 1.82 | G7: 40 | H7: 2.244 | I7: 40 | J7: 1.85 | K7: 40 | L7: 2.44 | M7: 35
A8: 9 | B8: 2.22 | C8: 40 | D8: 2.62 | E8: 15 | F8: 2.25 | G8: 40 | H8: 3.05 | I8: 40 | J8: 2.41 | K8: 28 | L8: 3.57 | M8: 31
A9: 10 | B9: 3.03 | C9: 40 | D9: 3.87 | E9: 18 | F9: 3.14 | G9: 40 | H9: 3.95 | I9: 40 | J9: 3.32 | K9: 27 | L9: 4.925 | M9: 40
A10: 11 | B10: 3.99 | C10: 40 | D10: 5.11 | E10: 24 | F10: 3.96 | G10: 40 | H10: 4.603 | I10: 29 | J10: 5.64 | K10: 11 | L10: 5.675 | M10: 40
A11: 12 | B11: 5.32 | C11: 40 | D11: 5.82 | E11: 18 | F11: 4.73 | G11: 40 | H11: 6.29 | I11: 11 | J11: 6 | K11: 17 | L11: 7.33 | M11: 40
A12: 13 | B12: 5.66 | C12: 40 | D12: 7.55 | E12: 18 | F12: 6.02 | G12: 40 | H12: 7.66 | I12: 19 | J12: 7.96 | K12: 28 | L12: 9.05 | M12: 36
A13: 14 | B13: 6.64 | C13: 40 | F13: 6.69 | G13: 40 | H13: 9.1 | I13: 10 | J13: 9.09 | K13: 40 | L13: 10.05 | M13: 29
A14: 15 | B14: 7.9 | C14: 40 | F14: 7.7 | G14: 40 | H14: 10.7 | I14: 17 | J14: 11.36 | K14: 40 | L14: 13.14 | M14: 21
A15: 16 | B15: 9.16 | C15: 40 | F15: 9.027 | G15: 40 | H15: 12.38 | I15: 20 | J15: 12.5 | K15: 40
A16: 17 | B16: 10.74 | C16: 40 | F16: 12.19 | G16: 40 | J16: 14.73 | K16: 40
A17: 18 | B17: 13.68 | C17: 40 | F17: 14.47 | G17: 40 | J17: 17.41 | K17: 40
A18: 19 | B18: 16.69 | C18: 40 | F18: 15.699 | G18: 40 | J18: 19.89 | K18: 40
A19: 20 | B19: 17.28 | C19: 40 | F19: 18.669 | G19: 40 | J19: 19.2 | K19: 40
A20: 21 | B20: 21.4 | C20: 40 | F20: 19.8 | G20: 40 | J20: 24.39 | K20: 40
A21: 22 | B21: 21.26 | C21: 40 | F21: 24.21 | G21: 40 | J21: 27.59 | K21: 40
A22: 23 | B22: 21.94 | C22: 33 | F22: 26.13 | G22: 40 | J22: 31.4 | K22: 20
A23: 24 | B23: 26.39 | C23: 11 | F23: 28.26 | G23: 23
A24: 25 | F24: 36.36 | G24: 17
A25: 26 | F25: 42.699 | G25: 13
A26: 27
A27: 28
A28: 29
A29: 30
A30: 31
A31: 32
A32: 33
A33: 34
A34: 35
A35: 36

Sheet Bijlage 7
A1: Berekende ADV van de quagga- en driehoeksmosselen op de monsterlocaties
C3: Nieuwe methode (in schelp)
A4: Deelgebied | B4: Locatie | C4: Berekend ADV bugensis (mg/m2) | D4: Berekend ADV polymorpha (mg/m2)
A5: IJsselmeer Noord | B5: 1 | C5: 260.5 | D5: 438.6
A6: IJsselmeer Noord | B6: 2 | C6: 0 | D6: 0
A7: IJsselmeer Noord | B7: 3 | C7: 0 | D7: 0
A8: IJsselmeer Noord | B8: 4 | C8: 0 | D8: 0
A9: IJsselmeer Noord | B9: 5 | C9: 6513.2 | D9: 2361.9
A10: IJsselmeer Noord | B10: 6 | C10: 0 | D10: 0
A11: IJsselmeer Noord | B11: 7 | C11: 434.2 | D11: 101.2
A12: IJsselmeer Noord | B12: 8 | C12: 0 | D12: 0
A13: IJsselmeer Noord | B13: 9 | C13: 86.8 | D13: 674.8
A14: IJsselmeer Noord | B14: 10 | C14: 0 | D14: 0
A15: IJsselmeer Noord | B15: 11 | C15: 0 | D15: 16.9
A16: IJsselmeer Noord | B16: 12 | C16: 21.7 | D16: 67.5
... A144: IJsselmeer Zuid | B144: 140 | C144: 19482.9 | D144: 1766.1
