Workbook

Sheet Informatie
A1: Bemonsteringsdata: 16 oktober t/m 1 november
A3: Op alle locaties is een Van Veenhapper gebruikt met bemonsteringsoppervlak van 260 cm2 | E3: =5*260 -> 1300 | F3: =E3/10000 -> 0.13
A4: Op elke locatie zijn 5 happen genomen, binnen 10 meter vanaf de hoofdlocatie
A6: Asvrij droog vleesgewicht (ADV) bepaald van driehoeks- en quaggamosselen (dit voor beide methoden (vlees verwijderd en schelp aan 1 kant open))
A7: Drooggewicht: 48 uur bij 760graden C.
A8: Asrest: 4 uur bij 490 graden C.
A10: Sedimenttype: | D10: Percentage lutumgehalte | H10: PAS= Primair aanhechtingsubstraat:
A11: K | B11: Klei | D11: Omschrijving | E11: Beoordeling | F11: Percentage | H11: D | I11: Dreissena
A12: Z | B12: Zand | D12: Klei-arm zand. Strandzand | E12: Schuurt tussen duim en wijsvinger. | F12: 0-2% | H12: M | I12: Mytilus
A13: Z/s | B13: Meest zand (met slib) | D13: Kleihoudend zand | E13: Iets vuil, smeert ietsje. Schuurt nog onverminderd, klein slibwolkje als je het in een plas gooit. | F13: 2-5% | H13: C | I13: Corbicula
A14: V | B14: Veen | D14: Kleiig zand/ slibbig zand | E14: Smeert. Bij knijpen gaat een klein deel tussen de vingers door. | F14: 5-8% | H14: Z | I14: Zuiderzeeschelpen
A15: S | B15: Slib | D15: Zeer lichte zavel | E15: Smeert goed. Bij knijpen grotendeels weg, iets zand over in de hand. | F15: 8-12% | H15: N | I15: Najaden (o.a. zwanenmossels)
A16: S/z | B16: Meest slib (met zand) | D16: Matig lichte zavel | E16: Smeert goed. Zand alleen nog goed te voelen tussen duim en wijsvinger. | F16: 12-17% | H16: W | I16: Waterplanten
A17: G | B17: Grind | D17: Zware zavel | E17: Smeert goed. Bijna geen zand meer te voelen. Klei wil niet meer van vingers afspoelen. | F17: 17-25% | I17: Overig
A18: X | B18: Grof materiaal (stenen, schelpen) | D18: Lichte klei | E18: Bijna stopverf, als molykote tussen duim en vinger. Zand alleen nog te proeven. | F18: 25-35%
A19: Y | B19: Anders | D19: Zware klei | E19: Bijna stopverf, als molykote tussen duim en vinger. Geen zand meer te proeven. | F19: >35%

Sheet Bijlage 4
C1: Coordinaten gepland (RD) | E1: Coordinaten uitgevoerd (RD) | I1: Biovolumes (ml) | K1: Biovolume (ml) | M1: Aantallen | O1: Sedimenttype (k, z, z/s, v, y, s, s/z, g, x) per hap | T1: Percentage lutum per hap | Y1: PAS (D, M, C, Z, N, W, O) per hap
A2: Deelgebied | B2: Locatie | C2: x | D2: y | E2: x | F2: y | G2: Datum | H2: Waterdiepte (m) | I2: Driehoeksmossel | J2: Quaggamossel | K2: Mytilidae | L2: Corbicula | M2: Corbicula | N2: Najaden | O2: 1 | P2: 2 | Q2: 3 | R2: 4 | S2: 5 | T2: 1 | U2: 2 | V2: 3 | W2: 4 | X2: 5 | Y2: 1 | Z2: 2 | AA2: 3 | AB2: 4 | AC2: 5 | AD2: Monsters lab | AE2: Weer | AF2: Opmerkingen
A3: Markermeer Noord | B3: 1 | C3: 147000 | D3: 521000 | E3: 146998.45 | F3: 520990.13 | G3: 45580 | H3: 2.572 | I3: 2.7 | J3: 5.8 | K3: - | L3: - | M3: - | N3: - | O3: z/s | P3: z | Q3: z | R3: z | S3: z | T3: 12-17 | U3: 8-12 | V3: 8-12 | W3: 8-12 | X3: 8-12 | Y3: - | Z3: z | AA3: z | AB3: z,d | AC3: z | AD3: Ja | AE3: Bewolkt, ZO3-4, 14 C° | AF3: -
A4: Markermeer Noord | B4: 2 | C4: 151000 | D4: 521000 | E4: 151005.13 | F4: 520990.46 | G4: 45580 | H4: 1.772 | I4: 0 | J4: 0.1 | K4: - | L4: 2 | M4: 5 | N4: - | O4: z | P4: s | Q4: z | R4: z | S4: z | T4: 8-12 | U4: 17-25 | V4: 8-12 | W4: 8-12 | X4: 8-12 | Y4: - | Z4: - | AA4: - | AB4: - | AC4: - | AD4: Nee | AE4: Bewolkt, ZO3-4, 14 C° | AF4: -
A5: Markermeer Noord | B5: 3 | C5: 145000 | D5: 519000 | E5: 144991.18 | F5: 518990.92 | G5: 45580 | H5: 2.476 | I5: 0 | J5: 0.2 | K5: - | L5: - | M5: - | N5: - | O5: z | P5: z | Q5: z | R5: z/s | S5: z | T5: 8-12 | U5: 8-12 | V5: 12-17 | W5: 12-17 | X5: 8-12 | Y5: - | Z5: - | AA5: - | AB5: d | AC5: - | AD5: Nee | AE5: Bewolkt, ZO3-4, 14 C° | AF5: -
A6: Markermeer Noord | B6: 4 | C6: 149000 | D6: 519000 | E6: 149007.99 | F6: 519008.06 | G6: 45580 | H6: 1.852 | I6: 0 | J6: 1.2 | K6: - | L6: - | M6: - | N6: - | O6: z | P6: z | Q6: z | R6: z | S6: z | T6: 8-12 | U6: 8-12 | V6: 8-12 | W6: 8-12 | X6: 8-12 | Y6: - | Z6: z | AA6: z | AB6: - | AC6: z | AD6: Nee | AE6: Bewolkt, ZO3-4, 14 C° | AF6: -
A7: Markermeer Noord | B7: 5 | C7: 152352.3 | D7: 518746 | E7: 152356.66 | F7: 518746.96 | G7: 45580 | H7: 2.394 | I7: 1 | J7: 3.5 | K7: - | L7: 1 | M7: 3 | N7: - | O7: z | P7: z | Q7: z | R7: z | S7: z | T7: 8-12 | U7: 8-12 | V7: 8-12 | W7: 8-12 | X7: 8-12 | Y7: - | Z7: z | AA7: - | AB7: z | AC7: d,c | AD7: Nee | AE7: Bewolkt, ZO3-4, 14 C° | AF7: -
A8: Hoornse Hop | B8: 6 | C8: 134900 | D8: 516600 | E8: 134895.51 | F8: 516590.09 | G8: 45579 | H8: 2.852 | I8: 0.1 | J8: 0.3 | K8: - | L8: - | M8: - | N8: - | O8: k | P8: k | Q8: s/z | R8: k | S8: k | T8: 17-25 | U8: 12-17 | V8: 12-17 | W8: >35 | X8: >35 | Y8: - | Z8: - | AA8: - | AB8: - | AC8: d | AD8: Nee | AE8: Bewolkt, O1-2, 12 C° | AF8: -
A9: Markermeer Noord | B9: 7 | C9: 143000 | D9: 517000 | E9: 143003.91 | F9: 517005.39 | G9: 45580 | H9: 3.032 | I9: 2.9 | J9: 6.2 | K9: - | L9: - | M9: - | N9: - | O9: z | P9: z | Q9: z | R9: s/z | S9: z/s | T9: 5-8 | U9: 5-8 | V9: 5-8 | W9: 12-17 | X9: 8-12 | Y9: z | Z9: d | AA9: z | AB9: z | AC9: z,d | AD9: Ja | AE9: Bewolkt, ZO3-4, 14 C° | AF9: -
A10: Markermeer Noord | B10: 8 | C10: 147000 | D10: 517000 | E10: 146976.37 | F10: 517006.29 | G10: 45580 | H10: 3.492 | I10: 3.7 | J10: 6.5 | K10: - | L10: - | M10: - | N10: - | O10: k | P10: k | Q10: s/z | R10: k | S10: s/z | T10: >35 | U10: >35 | V10: 12-17 | W10: >35 | X10: 12-17 | Y10: - | Z10: z | AA10: z,d | AB10: - | AC10: z,d | AD10: Ja | AE10: Bewolkt, ZO3-4, 14 C° | AF10: -
A11: Markermeer Noord | B11: 9 | C11: 151000 | D11: 517000 | E11: 151013.11 | F11: 516990.33 | G11: 45580 | H11: 2.748 | I11: 0 | J11: 0.9 | K11: - | L11: - | M11: - | N11: - | O11: z | P11: z | Q11: z | R11: z | S11: z | T11: 8-12 | U11: 8-12 | V11: 8-12 | W11: 8-12 | X11: 8-12 | Y11: z | Z11: d | AA11: - | AB11: - | AC11: - | AD11: Nee | AE11: Bewolkt, ZO3-4, 14 C° | AF11: -
A12: Markermeer Noord | B12: 10 | C12: 154650.75 | D12: 516758.7 | E12: 154663.15 | F12: 516763.18 | G12: 45582 | H12: 2.49 | I12: 1.1 | J12: 0.2 | K12: - | L12: 2.5 | M12: 3 | N12: - | O12: z | P12: z | Q12: z | R12: z | S12: z | T12: 2-5 | U12: 2-5 | V12: 2-5 | W12: 2-5 | X12: 2-5 | Y12: z | Z12: - | AA12: - | AB12: d | AC12: - | AD12: Nee | AE12: Bewolkt, Z1-3, 20 C° | AF12: -
A13: Hoornse Hop | B13: 11 | C13: 133000 | D13: 515000 | E13: 133004.01 | F13: 515004.69 | G13: 45579 | H13: 3.076 | I13: 20.8 | J13: 26.2 | K13: - | L13: - | M13: - | N13: - | O13: z | P13: z | Q13: z | R13: z | S13: k | T13: 8-12 | U13: 8-12 | V13: 8-12 | W13: 8-12 | X13: 25-35 | Y13: z | Z13: z | AA13: z | AB13: z,d | AC13: z,d | AD13: Ja | AE13: Bewolkt, O1-2, 12 C° | AF13: -
A14: Hoornse Hop | B14: 12 | C14: 137000 | D14: 515000 | E14: 136995.4 | F14: 514998.75 | G14: 45579 | H14: 3.284 | I14: 0.2 | J14: 0 | K14: - | L14: - | M14: - | N14: - | O14: k | P14: z/s | Q14: z | R14: z/s | S14: z/s | T14: 25-35 | U14: 12-17 | V14: 12-17 | W14: 12-17 | X14: 12-17 | Y14: - | Z14: - | AA14: - | AB14: z | AC14: z | AD14: Nee | AE14: Bewolkt, O1-2, 12 C° | AF14: -
A15: Markermeer Noord | B15: 13 | C15: 141000 | D15: 515000 | E15: 140999.92 | F15: 514998.24 | G15: 45580 | H15: 3.532 | I15: 1 | J15: 4 | K15: - | L15: - | M15: - | N15: - | O15: z,x | P15: z,x | Q15: z,x | R15: z,x | S15: s/z | T15: 8-12 | U15: 8-12 | V15: 8-12 | W15: 8-12 | X15: 12-17 | Y15: - | Z15: z | AA15: z,d | AB15: z | AC15: z | AD15: Nee | AE15: Bewolkt, ZO3-4, 14 C° | AF15: -
A16: Markermeer Noord | B16: 14 | C16: 145000 | D16: 515000 | E16: 144995.34 | F16: 514993.03 | G16: 45580 | H16: 3.656 | I16: 1.6 | J16: 5 | K16: - | L16: - | M16: - | N16: - | O16: z | P16: z/s | Q16: z/s | R16: z/s | S16: z/s | T16: 8-12 | U16: 12-17 | V16: 12-17 | W16: 12-17 | X16: 12-17 | Y16: - | Z16: - | AA16: - | AB16: - | AC16: - | AD16: Nee | AE16: Bewolkt, ZO3-4, 14 C° | AF16: -
A17: Markermeer Noord | B17: 15 | C17: 149000 | D17: 515000 | E17: 149000.7 | F17: 514982.15 | G17: 45580 | H17: 3.352 | I17: 0 | J17: 2.4 | K17: - | L17: - | M17: - | N17: - | O17: z | P17: z | Q17: z | R17: z | S17: z | T17: 8-12 | U17: 8-12 | V17: 8-12 | W17: 8-12 | X17: 8-12 | Y17: - | Z17: z | AA17: z | AB17: z | AC17: z | AD17: Nee | AE17: Bewolkt, ZO3-4, 14 C° | AF17: -
A18: Markermeer Noord | B18: 16 | C18: 153000 | D18: 515000 | E18: 152996.33 | F18: 515009.05 | G18: 45582 | H18: 3.358 | I18: 1.5 | J18: 1 | K18: - | L18: 2 | M18: 2 | N18: - | O18: z | P18: z | Q18: z | R18: z | S18: z | T18: 2-5 | U18: 2-5 | V18: 2-5 | W18: 2-5 | X18: 2-5 | Y18: c | Z18: - | AA18: - | AB18: - | AC18: z,d | AD18: Nee | AE18: Bewolkt, Z1-3, 20 C° | AF18: -
A19: Markermeer Noord | B19: 17 | C19: 157000 | D19: 515000 | E19: 156996.47 | F19: 514986.69 | G19: 45582 | H19: 3.892 | I19: 1.2 | J19: 2.5 | K19: - | L19: 3 | M19: 6 | N19: - | O19: z/s | P19: z/s | Q19: z/s | R19: z/s | S19: z/s | T19: 5-8 | U19: 5-8 | V19: 5-8 | W19: 5-8 | X19: 5-8 | Y19: z | Z19: z | AA19: - | AB19: c | AC19: - | AD19: Nee | AE19: Bewolkt, Z1-3, 20 C° | AF19: -
A20: Hoornse Hop | B20: 18 | C20: 131000 | D20: 513000 | E20: 131001.15 | F20: 513006.95 | G20: 45579 | H20: 2.42 | I20: 13.2 | J20: 22.3 | K20: - | L20: - | M20: - | N20: - | O20: z,x | P20: z,x | Q20: z,x | R20: z,x | S20: z,x | T20: 8-12 | U20: 8-12 | V20: 8-12 | W20: 8-12 | X20: 8-12 | Y20: z | Z20: z | AA20: z,d | AB20: z,d | AC20: z,d | AD20: Ja | AE20: Bewolkt, O1-2, 12 C° | AF20: -
A21: Hoornse Hop | B21: 19 | C21: 135000 | D21: 513000 | E21: 134999.75 | F21: 513004.59 | G21: 45579 | H21: 3.304 | I21: 0.9 | J21: 0.9 | K21: - | L21: - | M21: - | N21: - | O21: k,x | P21: k | Q21: k | R21: k | S21: k | T21: >35 | U21: >35 | V21: >35 | W21: >35 | X21: >35 | Y21: z | Z21: - | AA21: z | AB21: z | AC21: - | AD21: Nee | AE21: Bewolkt, O1-2, 12 C° | AF21: -
A22: Hoornse Hop | B22: 20 | C22: 139000 | D22: 513000 | E22: 139010.25 | F22: 513001.44 | G22: 45579 | H22: 3.958 | I22: 0.8 | J22: 1.9 | K22: - | L22: - | M22: - | N22: - | O22: k,x | P22: k | Q22: k | R22: k | S22: k,x | T22: >35 | U22: 17-25 | V22: >35 | W22: >35 | X22: 25-35 | Y22: - | Z22: - | AA22: - | AB22: z | AC22: z,d | AD22: Nee | AE22: Bewolkt, O1-2, 12 C° | AF22: -
A23: Markermeer Noord | B23: 21 | C23: 143000 | D23: 513000 | E23: 142998.02 | F23: 512995.18 | G23: 45580 | H23: 3.835 | I23: 4.7 | J23: 7.5 | K23: - | L23: - | M23: - | N23: - | O23: z,x | P23: z,x | Q23: s | R23: z/s | S23: k | T23: 8-12 | U23: 8-12 | V23: 17-25 | W23: 12-17 | X23: 25-35 | Y23: z | Z23: z | AA23: z,d | AB23: z,d | AC23: z | AD23: Ja | AE23: Bewolkt, ZO3-4, 14 C° | AF23: -
A24: Markermeer Noord | B24: 22 | C24: 147000 | D24: 513000 | E24: 146995.48 | F24: 512998.27 | G24: 45580 | H24: 3.76 | I24: 1.1 | J24: 4 | K24: - | L24: - | M24: - | N24: - | O24: z/s | P24: z | Q24: z | R24: z/s | S24: z/s | T24: 12-17 | U24: 8-12 | V24: 8-12 | W24: 12-17 | X24: 12-17 | Y24: d | Z24: z,d | AA24: d | AB24: - | AC24: - | AD24: Nee | AE24: Bewolkt, ZO3-4, 14 C° | AF24: -
A25: Markermeer Noord | B25: 23 | C25: 151000 | D25: 513000 | E25: 151003.57 | F25: 512998.04 | G25: 45582 | H25: 3.756 | I25: 0 | J25: 0.4 | K25: - | L25: - | M25: - | N25: - | O25: z/s | P25: s/z | Q25: s/z | R25: s | S25: z/s | T25: 5-8 | U25: 8-12 | V25: 17-25 | W25: 17-25 | X25: 5-8 | Y25: z,d | Z25: - | AA25: - | AB25: - | AC25: z | AD25: Nee | AE25: Bewolkt, Z1-3, 20 C° | AF25: -
A26: Markermeer Noord | B26: 24 | C26: 155211.67 | D26: 513185.21 | E26: 155211.01 | F26: 513188.04 | G26: 45582 | H26: 3.426 | I26: 0 | J26: 0 | K26: - | L26: - | M26: - | N26: - | O26: s | P26: s | Q26: s | R26: s | S26: s | T26: 17-25 | U26: 17-25 | V26: 17-25 | W26: 17-25 | X26: 17-25 | Y26: - | Z26: - | AA26: - | AB26: - | AC26: - | AD26: Nee | AE26: Bewolkt, Z1-3, 20 C° | AF26: -
A27: Hoornse Hop | B27: 25 | C27: 133000 | D27: 511000 | E27: 133001.34 | F27: 510997.79 | G27: 45579 | H27: 3.004 | I27: 1.2 | J27: 3.9 | K27: - | L27: - | M27: - | N27: - | O27: k | P27: z,x | Q27: k | R27: z,x | S27: k | T27: >35 | U27: 12-17 | V27: 17-25 | W27: 12-17 | X27: >35 | Y27: z | Z27: z | AA27: z | AB27: z | AC27: z | AD27: Nee | AE27: Bewolkt, O1-2, 12 C° | AF27: -
A28: Hoornse Hop | B28: 26 | C28: 137000 | D28: 511000 | E28: 136999.53 | F28: 510994.62 | G28: 45579 | H28: 3.496 | I28: 1.1 | J28: 3.1 | K28: - | L28: - | M28: - | N28: - | O28: s | P28: k,x | Q28: k,x | R28: k,x | S28: s | T28: 12-17 | U28: 25-35 | V28: 25-35 | W28: 25-35 | X28: 17-25 | Y28: z | Z28: z | AA28: z | AB28: z | AC28: z | AD28: Nee | AE28: Bewolkt, O1-2, 12 C° | AF28: -
A29: Markermeer-Midden | B29: 27 | C29: 141000 | D29: 511000 | E29: 141004.7 | F29: 510998.26 | G29: 45580 | H29: 3.872 | I29: 0.01 | J29: 0.1 | K29: - | L29: - | M29: - | N29: - | O29: k | P29: s,k | Q29: k | R29: s/z | S29: s/z | T29: >35 | U29: 17-25 | V29: >35 | W29: 12-17 | X29: 12-17 | Y29: - | Z29: z | AA29: - | AB29: - | AC29: z | AD29: Nee | AE29: Bewolkt, ZO3-4, 14 C° | AF29: -
A30: Markermeer-Midden | B30: 28 | C30: 145000 | D30: 511000 | E30: 145005.88 | F30: 510992.93 | G30: 45580 | H30: 3.842 | I30: 0.01 | J30: 3 | K30: - | L30: - | M30: - | N30: - | O30: z/s | P30: z | Q30: z | R30: z | S30: z | T30: 12-17 | U30: 8-12 | V30: 8-12 | W30: 8-12 | X30: 8-12 | Y30: z | Z30: z | AA30: z | AB30: z | AC30: z | AD30: Nee | AE30: Bewolkt, ZO3-4, 14 C° | AF30: -
A31: Markermeer-Midden | B31: 29 | C31: 149000 | D31: 511000 | E31: 149013.95 | F31: 511016.22 | G31: 45582 | H31: 3.856 | I31: 0.6 | J31: 0.2 | K31: - | L31: - | M31: - | N31: - | O31: z/s | P31: z/s | Q31: z/s | R31: z/s | S31: z/s | T31: 8-12 | U31: 8-12 | V31: 8-12 | W31: 5-8 | X31: 8-12 | Y31: z | Z31: - | AA31: d | AB31: d | AC31: - | AD31: Nee | AE31: Bewolkt, Z1-3, 20 C° | AF31: -
A32: Markermeer-Midden | B32: 31 | C32: 157000 | D32: 511000 | E32: 157006.24 | F32: 511008.99 | G32: 45582 | H32: 3.894 | I32: 0 | J32: 0 | K32: - | L32: 1.5 | M32: 2 | N32: - | O32: s | P32: s | Q32: s | R32: s | S32: s | T32: 17-25 | U32: 17-25 | V32: 17-25 | W32: 17-25 | X32: 17-25 | Y32: - | Z32: - | AA32: - | AB32: - | AC32: - | AD32: Nee | AE32: Bewolkt, Z1-3, 20 C° | AF32: -
A33: Hoornse Hop | B33: 32 | C33: 131500 | D33: 509000 | E33: 131497.29 | F33: 509010.67 | G33: 45579 | H33: 2.172 | I33: 0.7 | J33: 1.9 | K33: - | L33: - | M33: - | N33: - | O33: v,k | P33: v | Q33: k | R33: v,k | S33: k | T33: 17-25 | U33: 12-17 | V33: 17-25 | W33: 25-35 | X33: 17-25 | Y33: - | Z33: z | AA33: z | AB33: - | AC33: z | AD33: Nee | AE33: Bewolkt, O1-2, 12 C° | AF33: -
A34: Hoornse Hop | B34: 33 | C34: 135000 | D34: 509000 | E34: 134999.4 | F34: 508996.04 | G34: 45579 | H34: 3.282 | I34: 3.1 | J34: 9.9 | K34: - | L34: - | M34: - | N34: - | O34: k,x | P34: k,x | Q34: x | R34: k,x | S34: k,x | T34: 17-25 | U34: 17-25 | V34: 8-12 | W34: 25-35 | X34: 25-35 | Y34: z | Z34: z | AA34: z | AB34: z | AC34: z | AD34: Ja | AE34: Bewolkt, O1-2, 12 C° | AF34: -
A35: Markermeer-Midden | B35: 34 | C35: 139000 | D35: 509000 | E35: 139002.15 | F35: 508999.06 | G35: 45579 | H35: 3.704 | I35: 1.2 | J35: 4 | K35: - | L35: - | M35: - | N35: - | O35: k | P35: k | Q35: k | R35: k | S35: k | T35: 25-35 | U35: >35 | V35: >35 | W35: >35 | X35: >35 | Y35: z | Z35: z | AA35: z | AB35: z | AC35: - | AD35: Nee | AE35: Bewolkt, O1-2, 12 C° | AF35: -
A36: Markermeer-Midden | B36: 35 | C36: 143000 | D36: 509000 | E36: 142991.2 | F36: 508989.91 | G36: 45580 | H36: 3.888 | I36: 0.1 | J36: 4 | K36: - | L36: - | M36: - | N36: - | O36: v,k | P36: k | Q36: s/z | R36: z | S36: k | T36: 25-35 | U36: 25-35 | V36: 17-25 | W36: 12-17 | X36: 25-35 | Y36: - | Z36: - | AA36: z | AB36: d | AC36: - | AD36: Nee | AE36: Bewolkt, ZO3-4, 14 C° | AF36: -
A37: Markermeer-Midden | B37: 36 | C37: 147000 | D37: 509000 | E37: 146998.13 | F37: 509006 | G37: 45582 | H37: 3.856 | I37: 1.2 | J37: 2 | K37: - | L37: - | M37: - | N37: - | O37: z | P37: z | Q37: z/s | R37: z/s | S37: z/s | T37: 2-5 | U37: 2-5 | V37: 2-5 | W37: 8-12 | X37: 8-12 | Y37: z | Z37: d | AA37: z,d | AB37: d | AC37: z | AD37: Nee | AE37: Bewolkt, Z1-3, 20 C° | AF37: -
A38: Markermeer-Midden | B38: 37 | C38: 151000 | D38: 509000 | E38: 150997.93 | F38: 508989.32 | G38: 45582 | H38: 4.278 | I38: 0.1 | J38: 0.4 | K38: - | L38: - | M38: - | N38: - | O38: z/s | P38: s/z | Q38: z/s | R38: s/z | S38: z/s | T38: 5-8 | U38: 12-17 | V38: 5-8 | W38: 12-17 | X38: 12-17 | Y38: d | Z38: - | AA38: - | AB38: z | AC38: - | AD38: Nee | AE38: Bewolkt, Z1-3, 20 C° | AF38: -
A39: Markermeer-Midden | B39: 39 | C39: 159000 | D39: 509000 | E39: 159002.61 | F39: 508990.01 | G39: 45582 | H39: 4.676 | I39: 1.4 | J39: 0.6 | K39: - | L39: - | M39: - | N39: - | O39: s/z | P39: s/z | Q39: s | R39: z/s | S39: s | T39: 12-17 | U39: 12-17 | V39: 17-25 | W39: 12-17 | X39: 17-25 | Y39: z,d | Z39: - | AA39: - | AB39: - | AC39: z | AD39: Nee | AE39: Bewolkt, Z1-3, 20 C° | AF39: -
A40: Hoornse Hop | B40: 40 | C40: 133000 | D40: 507000 | E40: 133001.95 | F40: 506988.7 | G40: 45579 | H40: 2.538 | I40: 3.4 | J40: 8.6 | K40: - | L40: - | M40: - | N40: - | O40: v,s | P40: v,k | Q40: k | R40: v,k | S40: k | T40: 12-17 | U40: 17-25 | V40: 17-25 | W40: 12-17 | X40: 25-35 | Y40: z | Z40: z | AA40: z | AB40: z | AC40: z | AD40: Nee | AE40: Bewolkt, O1-2, 12 C° | AF40: -
...

Sheet Bijlage 5a
A1: Aantallen aangetroffen mosselen in de meegenomen monsters
A3: Lengteklasse (mm) | B3: Markermeer Noord | D3: Markeermeer Midden | F3: Markermeer Zuid | H3: Ijmeer | J3: Hoornse Hop | L3: Totaal
B4: Bugensis | C4: Polymorpha | D4: Bugensis | E4: Polymorpha | F4: Bugensis | G4: Polymorpha | H4: Bugensis | I4: Polymorpha | J4: Bugensis | K4: Polymorpha
A5: 2 | B5: 54 | C5: 9 | F5: 9 | G5: 15 | H5: 9 | I5: 31 | J5: 5 | K5: 9 | L5: =SUM(B5:K5) -> 141
A6: 3 | B6: 18 | C6: 29 | D6: 3 | E6: 9 | F6: 4 | G6: 16 | H6: 8 | I6: 20 | J6: 8 | K6: 20 | L6: =SUM(B6:K6) -> 135
A7: 4 | C7: 22 | D7: 2 | E7: 11 | F7: 4 | G7: 9 | H7: 18 | I7: 10 | J7: 2 | K7: 9 | L7: =SUM(B7:K7) -> 87
A8: 5 | B8: 1 | C8: 38 | D8: 4 | E8: 39 | F8: 7 | G8: 24 | H8: 11 | I8: 39 | J8: 1 | K8: 22 | L8: =SUM(B8:K8) -> 186
A9: 6 | B9: 12 | C9: 36 | D9: 15 | E9: 37 | F9: 10 | G9: 42 | H9: 7 | I9: 39 | J9: 3 | K9: 47 | L9: =SUM(B9:K9) -> 248
A10: 7 | B10: 11 | C10: 43 | D10: 41 | E10: 49 | F10: 3 | G10: 43 | H10: 10 | I10: 47 | J10: 3 | K10: 77 | L10: =SUM(B10:K10) -> 327
A11: 8 | B11: 11 | C11: 44 | D11: 91 | E11: 62 | F11: 13 | G11: 42 | H11: 6 | I11: 36 | K11: 92 | L11: =SUM(B11:K11) -> 397
A12: 9 | B12: 32 | C12: 44 | D12: 43 | E12: 73 | F12: 9 | G12: 78 | H12: 3 | I12: 34 | J12: 5 | K12: 71 | L12: =SUM(B12:K12) -> 392
A13: 10 | B13: 30 | C13: 29 | D13: 42 | E13: 55 | F13: 11 | G13: 71 | H13: 5 | I13: 44 | J13: 6 | K13: 67 | L13: =SUM(B13:K13) -> 360
A14: 11 | B14: 39 | C14: 11 | D14: 26 | E14: 31 | F14: 12 | G14: 59 | H14: 9 | I14: 56 | J14: 5 | K14: 50 | L14: =SUM(B14:K14) -> 298
A15: 12 | B15: 23 | C15: 6 | D15: 45 | E15: 17 | F15: 21 | G15: 21 | H15: 15 | I15: 47 | J15: 17 | K15: 35 | L15: =SUM(B15:K15) -> 247
A16: 13 | B16: 13 | C16: 4 | D16: 49 | E16: 5 | F16: 30 | G16: 9 | H16: 21 | I16: 35 | J16: 29 | K16: 14 | L16: =SUM(B16:K16) -> 209
A17: 14 | B17: 18 | D17: 63 | F17: 35 | G17: 4 | H17: 21 | I17: 14 | J17: 26 | K17: 12 | L17: =SUM(B17:K17) -> 193
A18: 15 | B18: 14 | D18: 48 | F18: 30 | G18: 3 | H18: 22 | I18: 18 | J18: 37 | K18: 3 | L18: =SUM(B18:K18) -> 175
A19: 16 | B19: 10 | D19: 31 | F19: 41 | G19: 1 | H19: 29 | I19: 7 | J19: 34 | K19: 1 | L19: =SUM(B19:K19) -> 154
A20: 17 | B20: 8 | D20: 15 | F20: 40 | H20: 38 | I20: 2 | J20: 21 | K20: 1 | L20: =SUM(B20:K20) -> 125
A21: 18 | B21: 2 | D21: 8 | F21: 22 | H21: 32 | I21: 1 | J21: 12 | L21: =SUM(B21:K21) -> 77
A22: 19 | B22: 2 | D22: 6 | F22: 10 | H22: 24 | I22: 1 | J22: 6 | L22: =SUM(B22:K22) -> 49
A23: 20 | D23: 2 | F23: 4 | H23: 12 | J23: 7 | L23: =SUM(B23:K23) -> 25
A24: 21 | F24: 3 | H24: 6 | J24: 3 | L24: =SUM(B24:K24) -> 12
A25: 22 | F25: 1 | H25: 7 | J25: 1 | L25: =SUM(B25:K25) -> 9
A26: 23 | H26: 1 | L26: =SUM(B26:K26) -> 1
A27: 24 | L27: =SUM(B27:K27) -> 0
A28: 25 | L28: =SUM(B28:K28) -> 0
A29: 26 | L29: =SUM(B29:K29) -> 0
A30: 27 | L30: =SUM(B30:K30) -> 0
A31: 28 | L31: =SUM(B31:K31) -> 0
A32: 29 | L32: =SUM(B32:K32) -> 0
A33: 30 | L33: =SUM(B33:K33) -> 0
A34: 31 | L34: =SUM(B34:K34) -> 0
A35: 32 | L35: =SUM(B35:K35) -> 0
A36: 33 | L36: =SUM(B36:K36) -> 0
A37: 34 | L37: =SUM(B37:K37) -> 0
A38: 35 | L38: =SUM(B38:K38) -> 0
A39: 36 | L39: =SUM(B39:K39) -> 0
A40: Totaal | B40: =SUM(B5:B39) -> 298 | C40: =SUM(C5:C39) -> 315 | D40: =SUM(D5:D39) -> 534 | E40: =SUM(E5:E39) -> 388 | F40: =SUM(F5:F39) -> 319 | G40: =SUM(G5:G39) -> 437 | H40: =SUM(H5:H39) -> 314 | I40: =SUM(I5:I39) -> 481 | ... L40: =SUM(L5:L39) -> 3847
B42: Polymorpha | C42: =SUM(C40,E40,G40,I40,K40) -> 2151
...

Sheet Bijlage 5b
A1: Procentuele verspreiding van de lengteklassen per soort per deelgebied
A3: Lengteklasse (mm) | B3: Markermeer Noord | D3: Markerneer Midden | F3: Markermeer Zuid | H3: Ijmeer | J3: Hoornse Hop
B4: Bugensis | C4: Polymorpha | D4: Bugensis | E4: Polymorpha | F4: Bugensis | G4: Polymorpha | H4: Bugensis | I4: Polymorpha | J4: Bugensis | K4: Polymorpha
A5: 2 | B5: =('Bijlage 5a'!B5/(SUM('Bijlage 5a'!B$5:B$31))) -> 0.18120805 | C5: =('Bijlage 5a'!C5/(SUM('Bijlage 5a'!C$5:C$31))) -> 0.028571429 | D5: =('Bijlage 5a'!D5/(SUM('Bijlage 5a'!D$5:D$31))) -> 0 | E5: =('Bijlage 5a'!E5/(SUM('Bijlage 5a'!E$5:E$31))) -> 0 | F5: =('Bijlage 5a'!F5/(SUM('Bijlage 5a'!F$5:F$31))) -> 0.028213166 | G5: =('Bijlage 5a'!G5/(SUM('Bijlage 5a'!G$5:G$31))) -> 0.034324943 | H5: =('Bijlage 5a'!H5/(SUM('Bijlage 5a'!H$5:H$31))) -> 0.02866242 | I5: =('Bijlage 5a'!I5/(SUM('Bijlage 5a'!I$5:I$31))) -> 0.064449064 | ... K5: =('Bijlage 5a'!K5/(SUM('Bijlage 5a'!K$5:K$31))) -> 0.016981132
A6: 3 | B6: =('Bijlage 5a'!B6/(SUM('Bijlage 5a'!B$5:B$31))) -> 0.060402685 | C6: =('Bijlage 5a'!C6/(SUM('Bijlage 5a'!C$5:C$31))) -> 0.092063492 | D6: =('Bijlage 5a'!D6/(SUM('Bijlage 5a'!D$5:D$31))) -> 0.0056179775 | E6: =('Bijlage 5a'!E6/(SUM('Bijlage 5a'!E$5:E$31))) -> 0.023195876 | F6: =('Bijlage 5a'!F6/(SUM('Bijlage 5a'!F$5:F$31))) -> 0.012539185 | G6: =('Bijlage 5a'!G6/(SUM('Bijlage 5a'!G$5:G$31))) -> 0.036613272 | H6: =('Bijlage 5a'!H6/(SUM('Bijlage 5a'!H$5:H$31))) -> 0.025477707 | I6: =('Bijlage 5a'!I6/(SUM('Bijlage 5a'!I$5:I$31))) -> 0.041580042 | ... K6: =('Bijlage 5a'!K6/(SUM('Bijlage 5a'!K$5:K$31))) -> 0.037735849
A7: 4 | B7: =('Bijlage 5a'!B7/(SUM('Bijlage 5a'!B$5:B$31))) -> 0 | C7: =('Bijlage 5a'!C7/(SUM('Bijlage 5a'!C$5:C$31))) -> 0.06984127 | D7: =('Bijlage 5a'!D7/(SUM('Bijlage 5a'!D$5:D$31))) -> 0.0037453184 | E7: =('Bijlage 5a'!E7/(SUM('Bijlage 5a'!E$5:E$31))) -> 0.028350515 | F7: =('Bijlage 5a'!F7/(SUM('Bijlage 5a'!F$5:F$31))) -> 0.012539185 | G7: =('Bijlage 5a'!G7/(SUM('Bijlage 5a'!G$5:G$31))) -> 0.020594966 | H7: =('Bijlage 5a'!H7/(SUM('Bijlage 5a'!H$5:H$31))) -> 0.057324841 | I7: =('Bijlage 5a'!I7/(SUM('Bijlage 5a'!I$5:I$31))) -> 0.020790021 | ... K7: =('Bijlage 5a'!K7/(SUM('Bijlage 5a'!K$5:K$31))) -> 0.016981132
A8: 5 | B8: =('Bijlage 5a'!B8/(SUM('Bijlage 5a'!B$5:B$31))) -> 0.0033557047 | C8: =('Bijlage 5a'!C8/(SUM('Bijlage 5a'!C$5:C$31))) -> 0.12063492 | D8: =('Bijlage 5a'!D8/(SUM('Bijlage 5a'!D$5:D$31))) -> 0.0074906367 | E8: =('Bijlage 5a'!E8/(SUM('Bijlage 5a'!E$5:E$31))) -> 0.10051546 | F8: =('Bijlage 5a'!F8/(SUM('Bijlage 5a'!F$5:F$31))) -> 0.021943574 | G8: =('Bijlage 5a'!G8/(SUM('Bijlage 5a'!G$5:G$31))) -> 0.054919908 | H8: =('Bijlage 5a'!H8/(SUM('Bijlage 5a'!H$5:H$31))) -> 0.035031847 | I8: =('Bijlage 5a'!I8/(SUM('Bijlage 5a'!I$5:I$31))) -> 0.081081081 | ... K8: =('Bijlage 5a'!K8/(SUM('Bijlage 5a'!K$5:K$31))) -> 0.041509434
A9: 6 | B9: =('Bijlage 5a'!B9/(SUM('Bijlage 5a'!B$5:B$31))) -> 0.040268456 | C9: =('Bijlage 5a'!C9/(SUM('Bijlage 5a'!C$5:C$31))) -> 0.11428571 | D9: =('Bijlage 5a'!D9/(SUM('Bijlage 5a'!D$5:D$31))) -> 0.028089888 | E9: =('Bijlage 5a'!E9/(SUM('Bijlage 5a'!E$5:E$31))) -> 0.095360825 | F9: =('Bijlage 5a'!F9/(SUM('Bijlage 5a'!F$5:F$31))) -> 0.031347962 | G9: =('Bijlage 5a'!G9/(SUM('Bijlage 5a'!G$5:G$31))) -> 0.09610984 | H9: =('Bijlage 5a'!H9/(SUM('Bijlage 5a'!H$5:H$31))) -> 0.022292994 | I9: =('Bijlage 5a'!I9/(SUM('Bijlage 5a'!I$5:I$31))) -> 0.081081081 | ... K9: =('Bijlage 5a'!K9/(SUM('Bijlage 5a'!K$5:K$31))) -> 0.088679245
A10: 7 | B10: =('Bijlage 5a'!B10/(SUM('Bijlage 5a'!B$5:B$31))) -> 0.036912752 | C10: =('Bijlage 5a'!C10/(SUM('Bijlage 5a'!C$5:C$31))) -> 0.13650794 | D10: =('Bijlage 5a'!D10/(SUM('Bijlage 5a'!D$5:D$31))) -> 0.076779026 | E10: =('Bijlage 5a'!E10/(SUM('Bijlage 5a'!E$5:E$31))) -> 0.12628866 | F10: =('Bijlage 5a'!F10/(SUM('Bijlage 5a'!F$5:F$31))) -> 0.0094043887 | G10: =('Bijlage 5a'!G10/(SUM('Bijlage 5a'!G$5:G$31))) -> 0.098398169 | H10: =('Bijlage 5a'!H10/(SUM('Bijlage 5a'!H$5:H$31))) -> 0.031847134 | I10: =('Bijlage 5a'!I10/(SUM('Bijlage 5a'!I$5:I$31))) -> 0.097713098 | ... K10: =('Bijlage 5a'!K10/(SUM('Bijlage 5a'!K$5:K$31))) -> 0.14528302
A11: 8 | B11: =('Bijlage 5a'!B11/(SUM('Bijlage 5a'!B$5:B$31))) -> 0.036912752 | C11: =('Bijlage 5a'!C11/(SUM('Bijlage 5a'!C$5:C$31))) -> 0.13968254 | D11: =('Bijlage 5a'!D11/(SUM('Bijlage 5a'!D$5:D$31))) -> 0.17041199 | E11: =('Bijlage 5a'!E11/(SUM('Bijlage 5a'!E$5:E$31))) -> 0.15979381 | F11: =('Bijlage 5a'!F11/(SUM('Bijlage 5a'!F$5:F$31))) -> 0.040752351 | G11: =('Bijlage 5a'!G11/(SUM('Bijlage 5a'!G$5:G$31))) -> 0.09610984 | H11: =('Bijlage 5a'!H11/(SUM('Bijlage 5a'!H$5:H$31))) -> 0.01910828 | I11: =('Bijlage 5a'!I11/(SUM('Bijlage 5a'!I$5:I$31))) -> 0.074844075 | ... K11: =('Bijlage 5a'!K11/(SUM('Bijlage 5a'!K$5:K$31))) -> 0.17358491
A12: 9 | B12: =('Bijlage 5a'!B12/(SUM('Bijlage 5a'!B$5:B$31))) -> 0.10738255 | C12: =('Bijlage 5a'!C12/(SUM('Bijlage 5a'!C$5:C$31))) -> 0.13968254 | D12: =('Bijlage 5a'!D12/(SUM('Bijlage 5a'!D$5:D$31))) -> 0.080524345 | E12: =('Bijlage 5a'!E12/(SUM('Bijlage 5a'!E$5:E$31))) -> 0.18814433 | F12: =('Bijlage 5a'!F12/(SUM('Bijlage 5a'!F$5:F$31))) -> 0.028213166 | G12: =('Bijlage 5a'!G12/(SUM('Bijlage 5a'!G$5:G$31))) -> 0.1784897 | H12: =('Bijlage 5a'!H12/(SUM('Bijlage 5a'!H$5:H$31))) -> 0.0095541401 | I12: =('Bijlage 5a'!I12/(SUM('Bijlage 5a'!I$5:I$31))) -> 0.070686071 | ... K12: =('Bijlage 5a'!K12/(SUM('Bijlage 5a'!K$5:K$31))) -> 0.13396226
A13: 10 | B13: =('Bijlage 5a'!B13/(SUM('Bijlage 5a'!B$5:B$31))) -> 0.10067114 | C13: =('Bijlage 5a'!C13/(SUM('Bijlage 5a'!C$5:C$31))) -> 0.092063492 | D13: =('Bijlage 5a'!D13/(SUM('Bijlage 5a'!D$5:D$31))) -> 0.078651685 | E13: =('Bijlage 5a'!E13/(SUM('Bijlage 5a'!E$5:E$31))) -> 0.14175258 | F13: =('Bijlage 5a'!F13/(SUM('Bijlage 5a'!F$5:F$31))) -> 0.034482759 | G13: =('Bijlage 5a'!G13/(SUM('Bijlage 5a'!G$5:G$31))) -> 0.1624714 | H13: =('Bijlage 5a'!H13/(SUM('Bijlage 5a'!H$5:H$31))) -> 0.015923567 | I13: =('Bijlage 5a'!I13/(SUM('Bijlage 5a'!I$5:I$31))) -> 0.091476091 | ... K13: =('Bijlage 5a'!K13/(SUM('Bijlage 5a'!K$5:K$31))) -> 0.12641509
A14: 11 | B14: =('Bijlage 5a'!B14/(SUM('Bijlage 5a'!B$5:B$31))) -> 0.13087248 | C14: =('Bijlage 5a'!C14/(SUM('Bijlage 5a'!C$5:C$31))) -> 0.034920635 | D14: =('Bijlage 5a'!D14/(SUM('Bijlage 5a'!D$5:D$31))) -> 0.048689139 | E14: =('Bijlage 5a'!E14/(SUM('Bijlage 5a'!E$5:E$31))) -> 0.079896907 | F14: =('Bijlage 5a'!F14/(SUM('Bijlage 5a'!F$5:F$31))) -> 0.037617555 | G14: =('Bijlage 5a'!G14/(SUM('Bijlage 5a'!G$5:G$31))) -> 0.13501144 | H14: =('Bijlage 5a'!H14/(SUM('Bijlage 5a'!H$5:H$31))) -> 0.02866242 | I14: =('Bijlage 5a'!I14/(SUM('Bijlage 5a'!I$5:I$31))) -> 0.11642412 | ... K14: =('Bijlage 5a'!K14/(SUM('Bijlage 5a'!K$5:K$31))) -> 0.094339623
A15: 12 | B15: =('Bijlage 5a'!B15/(SUM('Bijlage 5a'!B$5:B$31))) -> 0.077181208 | C15: =('Bijlage 5a'!C15/(SUM('Bijlage 5a'!C$5:C$31))) -> 0.019047619 | D15: =('Bijlage 5a'!D15/(SUM('Bijlage 5a'!D$5:D$31))) -> 0.084269663 | E15: =('Bijlage 5a'!E15/(SUM('Bijlage 5a'!E$5:E$31))) -> 0.043814433 | F15: =('Bijlage 5a'!F15/(SUM('Bijlage 5a'!F$5:F$31))) -> 0.065830721 | G15: =('Bijlage 5a'!G15/(SUM('Bijlage 5a'!G$5:G$31))) -> 0.04805492 | H15: =('Bijlage 5a'!H15/(SUM('Bijlage 5a'!H$5:H$31))) -> 0.047770701 | I15: =('Bijlage 5a'!I15/(SUM('Bijlage 5a'!I$5:I$31))) -> 0.097713098 | ... K15: =('Bijlage 5a'!K15/(SUM('Bijlage 5a'!K$5:K$31))) -> 0.066037736
A16: 13 | B16: =('Bijlage 5a'!B16/(SUM('Bijlage 5a'!B$5:B$31))) -> 0.043624161 | C16: =('Bijlage 5a'!C16/(SUM('Bijlage 5a'!C$5:C$31))) -> 0.012698413 | D16: =('Bijlage 5a'!D16/(SUM('Bijlage 5a'!D$5:D$31))) -> 0.0917603 | E16: =('Bijlage 5a'!E16/(SUM('Bijlage 5a'!E$5:E$31))) -> 0.012886598 | F16: =('Bijlage 5a'!F16/(SUM('Bijlage 5a'!F$5:F$31))) -> 0.094043887 | G16: =('Bijlage 5a'!G16/(SUM('Bijlage 5a'!G$5:G$31))) -> 0.020594966 | H16: =('Bijlage 5a'!H16/(SUM('Bijlage 5a'!H$5:H$31))) -> 0.066878981 | I16: =('Bijlage 5a'!I16/(SUM('Bijlage 5a'!I$5:I$31))) -> 0.072765073 | ... K16: =('Bijlage 5a'!K16/(SUM('Bijlage 5a'!K$5:K$31))) -> 0.026415094
A17: 14 | B17: =('Bijlage 5a'!B17/(SUM('Bijlage 5a'!B$5:B$31))) -> 0.060402685 | D17: =('Bijlage 5a'!D17/(SUM('Bijlage 5a'!D$5:D$31))) -> 0.11797753 | F17: =('Bijlage 5a'!F17/(SUM('Bijlage 5a'!F$5:F$31))) -> 0.10971787 | G17: =('Bijlage 5a'!G17/(SUM('Bijlage 5a'!G$5:G$31))) -> 0.0091533181 | H17: =('Bijlage 5a'!H17/(SUM('Bijlage 5a'!H$5:H$31))) -> 0.066878981 | I17: =('Bijlage 5a'!I17/(SUM('Bijlage 5a'!I$5:I$31))) -> 0.029106029 | J17: =('Bijlage 5a'!J17/(SUM('Bijlage 5a'!J$5:J$31))) -> 0.11255411 | K17: =('Bijlage 5a'!K17/(SUM('Bijlage 5a'!K$5:K$31))) -> 0.022641509
A18: 15 | B18: =('Bijlage 5a'!B18/(SUM('Bijlage 5a'!B$5:B$31))) -> 0.046979866 | D18: =('Bijlage 5a'!D18/(SUM('Bijlage 5a'!D$5:D$31))) -> 0.08988764 | F18: =('Bijlage 5a'!F18/(SUM('Bijlage 5a'!F$5:F$31))) -> 0.094043887 | G18: =('Bijlage 5a'!G18/(SUM('Bijlage 5a'!G$5:G$31))) -> 0.0068649886 | H18: =('Bijlage 5a'!H18/(SUM('Bijlage 5a'!H$5:H$31))) -> 0.070063694 | I18: =('Bijlage 5a'!I18/(SUM('Bijlage 5a'!I$5:I$31))) -> 0.037422037 | J18: =('Bijlage 5a'!J18/(SUM('Bijlage 5a'!J$5:J$31))) -> 0.16017316 | K18: =('Bijlage 5a'!K18/(SUM('Bijlage 5a'!K$5:K$31))) -> 0.0056603774
A19: 16 | B19: =('Bijlage 5a'!B19/(SUM('Bijlage 5a'!B$5:B$31))) -> 0.033557047 | D19: =('Bijlage 5a'!D19/(SUM('Bijlage 5a'!D$5:D$31))) -> 0.058052434 | F19: =('Bijlage 5a'!F19/(SUM('Bijlage 5a'!F$5:F$31))) -> 0.12852665 | G19: =('Bijlage 5a'!G19/(SUM('Bijlage 5a'!G$5:G$31))) -> 0.0022883295 | H19: =('Bijlage 5a'!H19/(SUM('Bijlage 5a'!H$5:H$31))) -> 0.092356688 | I19: =('Bijlage 5a'!I19/(SUM('Bijlage 5a'!I$5:I$31))) -> 0.014553015 | J19: =('Bijlage 5a'!J19/(SUM('Bijlage 5a'!J$5:J$31))) -> 0.14718615 | K19: =('Bijlage 5a'!K19/(SUM('Bijlage 5a'!K$5:K$31))) -> 0.0018867925
A20: 17 | B20: =('Bijlage 5a'!B20/(SUM('Bijlage 5a'!B$5:B$31))) -> 0.026845638 | D20: =('Bijlage 5a'!D20/(SUM('Bijlage 5a'!D$5:D$31))) -> 0.028089888 | F20: =('Bijlage 5a'!F20/(SUM('Bijlage 5a'!F$5:F$31))) -> 0.12539185 | H20: =('Bijlage 5a'!H20/(SUM('Bijlage 5a'!H$5:H$31))) -> 0.12101911 | I20: =('Bijlage 5a'!I20/(SUM('Bijlage 5a'!I$5:I$31))) -> 0.0041580042 | J20: =('Bijlage 5a'!J20/(SUM('Bijlage 5a'!J$5:J$31))) -> 0.090909091 | K20: =('Bijlage 5a'!K20/(SUM('Bijlage 5a'!K$5:K$31))) -> 0.0018867925
A21: 18 | B21: =('Bijlage 5a'!B21/(SUM('Bijlage 5a'!B$5:B$31))) -> 0.0067114094 | D21: =('Bijlage 5a'!D21/(SUM('Bijlage 5a'!D$5:D$31))) -> 0.014981273 | F21: =('Bijlage 5a'!F21/(SUM('Bijlage 5a'!F$5:F$31))) -> 0.068965517 | H21: =('Bijlage 5a'!H21/(SUM('Bijlage 5a'!H$5:H$31))) -> 0.10191083 | I21: =('Bijlage 5a'!I21/(SUM('Bijlage 5a'!I$5:I$31))) -> 0.0020790021 | J21: =('Bijlage 5a'!J21/(SUM('Bijlage 5a'!J$5:J$31))) -> 0.051948052
A22: 19 | B22: =('Bijlage 5a'!B22/(SUM('Bijlage 5a'!B$5:B$31))) -> 0.0067114094 | D22: =('Bijlage 5a'!D22/(SUM('Bijlage 5a'!D$5:D$31))) -> 0.011235955 | F22: =('Bijlage 5a'!F22/(SUM('Bijlage 5a'!F$5:F$31))) -> 0.031347962 | H22: =('Bijlage 5a'!H22/(SUM('Bijlage 5a'!H$5:H$31))) -> 0.076433121 | I22: =('Bijlage 5a'!I22/(SUM('Bijlage 5a'!I$5:I$31))) -> 0.0020790021 | J22: =('Bijlage 5a'!J22/(SUM('Bijlage 5a'!J$5:J$31))) -> 0.025974026
A23: 20 | D23: =('Bijlage 5a'!D23/(SUM('Bijlage 5a'!D$5:D$31))) -> 0.0037453184 | F23: =('Bijlage 5a'!F23/(SUM('Bijlage 5a'!F$5:F$31))) -> 0.012539185 | H23: =('Bijlage 5a'!H23/(SUM('Bijlage 5a'!H$5:H$31))) -> 0.038216561 | J23: =('Bijlage 5a'!J23/(SUM('Bijlage 5a'!J$5:J$31))) -> 0.03030303
A24: 21 | F24: =('Bijlage 5a'!F24/(SUM('Bijlage 5a'!F$5:F$31))) -> 0.0094043887 | H24: =('Bijlage 5a'!H24/(SUM('Bijlage 5a'!H$5:H$31))) -> 0.01910828 | J24: =('Bijlage 5a'!J24/(SUM('Bijlage 5a'!J$5:J$31))) -> 0.012987013
A25: 22 | F25: =('Bijlage 5a'!F25/(SUM('Bijlage 5a'!F$5:F$31))) -> 0.0031347962 | H25: =('Bijlage 5a'!H25/(SUM('Bijlage 5a'!H$5:H$31))) -> 0.022292994 | J25: =('Bijlage 5a'!J25/(SUM('Bijlage 5a'!J$5:J$31))) -> 0.0043290043
A26: 23 | H26: =('Bijlage 5a'!H26/(SUM('Bijlage 5a'!H$5:H$31))) -> 0.0031847134
A27: 24
A28: 25
A29: 26
A30: 27
A31: 28
A32: 29
A33: 30
A34: 31
A35: 32
A36: 33
A37: 34
A38: 35
A39: 36
A40: Totaal | B40: =SUM(B5:B39) -> 1 | C40: =SUM(C5:C39) -> 1 | D40: =SUM(D5:D39) -> 1 | E40: =SUM(E5:E39) -> 1 | F40: =SUM(F5:F39) -> 1 | G40: =SUM(G5:G39) -> 1 | H40: =SUM(H5:H39) -> 1 | I40: =SUM(I5:I39) -> 1 | ... K40: =SUM(K5:K39) -> 1

Sheet Bijlage 6
A1: Gemiddeld ADV van lengteklassen van de quagga- en driehoeksmossel in de deelgebieden
B2: Tabel 2: V4 van A2.120: Schelp aan 1 kant opengemaakt gehaald alvorens te verassen, vlees verast in schelp
A3: SL (mm) | B3: Markermeer Noord | F3: Markermeer Midden | J3: Markermeer Zuid | N3: Ijmeer | R3: Hoornse Hop
B4: D. bugensis | D4: D. polymorpha | F4: D. bugensis | H4: D. polymorpha | J4: D. bugensis | L4: D. polymorpha | N4: D. bugensis | P4: D. polymorpha | R4: D. bugensis | T4: D. polymorpha
B5: ADV/mossel | C5: N bugensis | D5: ADV/mossel | E5: N polymorpha | F5: ADV/mossel | G5: N bugensis | H5: ADV/mossel | I5: N polymorpha | J5: ADV/mossel | K5: N bugensis | L5: ADV/mossel | M5: N polymorpha | N5: ADV/mossel | O5: N bugensis | P5: ADV/mossel | Q5: N polymorpha | R5: ADV/mossel | S5: N bugensis | T5: ADV/mossel | U5: N polymorpha
A6: 7 | D6: 1.81 | E6: 25 | F6: 1.497 | G6: 25 | H6: 1.81 | I6: 25 | L6: 1.59 | M6: 25 | N6: 1.53 | O6: 10 | P6: 1.63 | Q6: 25 | T6: 1.87 | U6: 25
A7: 8 | B7: 1.97 | C7: 11 | D7: 2.898 | E7: 25 | F7: 1.75 | G7: 25 | H7: 2.48 | I7: 25 | J7: 1.76 | K7: 13 | L7: 2.23 | M7: 25 | P7: 2.31 | Q7: 25 | T7: 2.59 | U7: 25
A8: 9 | B8: 2.8652 | C8: 25 | D8: 5.26 | E8: 25 | F8: 1.942 | G8: 18 | H8: 3.197 | I8: 25 | L8: 3.31 | M8: 25 | P8: 3.29 | Q8: 25 | T8: 3.38 | U8: 25
A9: 10 | B9: 3.3852 | C9: 25 | D9: 8.414 | E9: 25 | F9: 3.0944 | G9: 25 | H9: 5.83 | I9: 25 | J9: 4.11 | K9: 11 | L9: 4.69 | M9: 25 | P9: 4.55 | Q9: 25 | T9: 4.6 | U9: 25
A10: 11 | B10: 4.2948 | C10: 25 | D10: 11.929 | E10: 11 | F10: 3.778 | G10: 25 | H10: 11.45 | I10: 25 | J10: 4.86 | K10: 12 | L10: 5.47 | M10: 25 | P10: 5.8 | Q10: 25 | T10: 6.24 | U10: 25
A11: 12 | B11: 5.797 | C11: 23 | F11: 4.4495 | G11: 20 | H11: 13.62 | I11: 17 | J11: 5.56 | K11: 21 | L11: 6.76 | M11: 21 | N11: 6.52 | O11: 15 | P11: 6.71 | Q11: 25 | R11: 6.31 | S11: 17 | T11: 9.63 | U11: 25
A12: 13 | B12: 7.425 | C12: 13 | F12: 6.69 | G12: 25 | J12: 6.91 | K12: 25 | N12: 8.51 | O12: 21 | P12: 9.6 | Q12: 25 | R12: 8.19 | S12: 25 | T12: 10.77 | U12: 14
A13: 14 | B13: 10.488 | C13: 18 | F13: 7.48 | G13: 25 | J13: 9.54 | K13: 25 | N13: 10.12 | O13: 21 | P13: 15.55 | Q13: 10 | R13: 9.45 | S13: 25 | T13: 12.61 | U13: 12
A14: 15 | B14: 11.323 | C14: 14 | F14: 8.866 | G14: 25 | J14: 10.4 | K14: 25 | N14: 12.45 | O14: 22 | P14: 22.96 | Q14: 10 | R14: 11.31 | S14: 25
A15: 16 | B15: 14.073 | C15: 10 | F15: 10.19 | G15: 25 | J15: 11.68 | K15: 25 | N15: 15.15 | O15: 25 | R15: 13.05 | S15: 25
A16: 17 | F16: 13.48 | G16: 15 | J16: 13.52 | K16: 25 | N16: 17.76 | O16: 25 | R16: 14.83 | S16: 21
A17: 18 | J17: 14.67 | K17: 22 | N17: 21.34 | O17: 25 | R17: 19.83 | S17: 12
A18: 19 | J18: 18.5 | K18: 10 | N18: 22.82 | O18: 24
A19: 20 | N19: 29.26 | O19: 10
A20: 21
A21: 22
A22: 23
A23: 24
A24: 25
A25: 26
A26: 27
A27: 28
A28: 29
A29: 30
A30: 31
A31: 32
... A35: 36

Sheet Bijlage 7
A1: Berekende ADV van de quagga- en driehoeksmosselen op de monsterlocaties
C3: Nieuwe methode (in schelp)
A4: Deelgebied | B4: Locatie | C4: Berekend ADV bugensis (mg/m2) | D4: Berekend ADV polymorpha (mg/m2)
A5: Markermeer Noord | B5: 1 | C5: 2471.5641 | D5: 2257.8181
A6: Markermeer Noord | B6: 2 | C6: 42.613175 | D6: 0
A7: Markermeer Noord | B7: 3 | C7: 85.226349 | D7: 0
A8: Markermeer Noord | B8: 4 | C8: 511.35809 | D8: 0
A9: Markermeer Noord | B9: 5 | C9: 1491.4611 | D9: 836.22894
A10: Hoornse Hop | B10: 6 | C10: 131.26591 | D10: 59.712422
A11: Markermeer Noord | B11: 7 | C11: 2642.0168 | D11: 2425.0639
A12: Markermeer Noord | B12: 8 | C12: 2769.8563 | D12: 3094.0471
A13: Markermeer Noord | B13: 9 | C13: 383.51857 | D13: 0
A14: Markermeer Noord | B14: 10 | C14: 85.226349 | D14: 919.85184
A15: Hoornse Hop | B15: 11 | C15: 11463.889 | D15: 12420.184
A16: Hoornse Hop | B16: 12 | C16: 0 | D16: 119.42484
... A89: IJmeer | B89: 88 | C89: 0 | D89: 0
A90: Gouwzee | B90: 89 | C90: =#N/A -> #N/A | D90: =#N/A -> #N/A
